Fail to get yarn configuration. /home/cbel/Desktop/YIHAN/venv/lib/python3.8/site-packages/jupyterlab/staging/yarn.js:4
(()=>{var Qge=Object.create;var AS=Object.defineProperty;var bge=Object.getOwnPropertyDescriptor;var Sge=Object.getOwnPropertyNames;var vge=Object.getPrototypeOf,xge=Object.prototype.hasOwnProperty;var J=(r=>typeof require<"u"?require:typeof Proxy<"u"?new Proxy(r,{get:(e,t)=>(typeof require<"u"?require:e)[t]}):r)(function(r){if(typeof require<"u")return require.apply(this,arguments);throw new Error('Dynamic require of "'+r+'" is not supported')});var Pge=(r,e)=>()=>(r&&(e=r(r=0)),e);var w=(r,e)=>()=>(e||r((e={exports:{}}).exports,e),e.exports),ut=(r,e)=>{for(var t in e)AS(r,t,{get:e[t],enumerable:!0})},Dge=(r,e,t,i)=>{if(e&&typeof e=="object"||typeof e=="function")for(let n of Sge(e))!xge.call(r,n)&&n!==t&&AS(r,n,{get:()=>e[n],enumerable:!(i=bge(e,n))||i.enumerable});return r};var Pe=(r,e,t)=>(t=r!=null?Qge(vge(r)):{},Dge(e||!r||!r.__esModule?AS(t,"default",{value:r,enumerable:!0}):t,r));var QK=w((GXe,BK)=>{BK.exports=wK;

SyntaxError: Unexpected token {
    at createScript (vm.js:80:10)
    at Object.runInThisContext (vm.js:139:10)
    at Module._compile (module.js:616:28)
    at Object.Module._extensions..js (module.js:663:10)
    at Module.load (module.js:565:32)
    at tryModuleLoad (module.js:505:12)
    at Function.Module._load (module.js:497:3)
    at Function.Module.runMain (module.js:693:10)
    at startup (bootstrap_node.js:188:16)
    at bootstrap_node.js:609:3

[I 2025-03-11 00:28:44.587 ServerApp] jupyter_lsp | extension was successfully linked.
[I 2025-03-11 00:28:44.590 ServerApp] jupyter_server_terminals | extension was successfully linked.
[I 2025-03-11 00:28:44.593 ServerApp] jupyterlab | extension was successfully linked.
[I 2025-03-11 00:28:44.596 ServerApp] notebook | extension was successfully linked.
[I 2025-03-11 00:28:44.597 ServerApp] Writing Jupyter server cookie secret to /home/cbel/.local/share/jupyter/runtime/jupyter_cookie_secret
[I 2025-03-11 00:28:44.710 ServerApp] notebook_shim | extension was successfully linked.
[I 2025-03-11 00:28:44.750 ServerApp] notebook_shim | extension was successfully loaded.
[I 2025-03-11 00:28:44.751 ServerApp] jupyter_lsp | extension was successfully loaded.
[I 2025-03-11 00:28:44.752 ServerApp] jupyter_server_terminals | extension was successfully loaded.
[I 2025-03-11 00:28:44.753 LabApp] JupyterLab extension loaded from /home/cbel/Desktop/YIHAN/venv/lib/python3.8/site-packages/jupyterlab
[I 2025-03-11 00:28:44.753 LabApp] JupyterLab application directory is /home/cbel/Desktop/YIHAN/venv/share/jupyter/lab
[I 2025-03-11 00:28:44.753 LabApp] Extension Manager is 'pypi'.
[I 2025-03-11 00:28:44.770 ServerApp] jupyterlab | extension was successfully loaded.
[I 2025-03-11 00:28:44.772 ServerApp] notebook | extension was successfully loaded.
[I 2025-03-11 00:28:44.773 ServerApp] Serving notebooks from local directory: /home/cbel/Desktop/YIHAN/unet
[I 2025-03-11 00:28:44.773 ServerApp] Jupyter Server 2.14.2 is running at:
[I 2025-03-11 00:28:44.773 ServerApp] http://localhost:8888/tree?token=9f276798b6fd05f2f04663f6639d67d49bdbbec144d0b914
[I 2025-03-11 00:28:44.773 ServerApp]     http://127.0.0.1:8888/tree?token=9f276798b6fd05f2f04663f6639d67d49bdbbec144d0b914
[I 2025-03-11 00:28:44.773 ServerApp] Use Control-C to stop this server and shut down all kernels (twice to skip confirmation).
[C 2025-03-11 00:28:44.774 ServerApp] 
    
    To access the server, open this file in a browser:
        file:///home/cbel/.local/share/jupyter/runtime/jpserver-6533-open.html
    Or copy and paste one of these URLs:
        http://localhost:8888/tree?token=9f276798b6fd05f2f04663f6639d67d49bdbbec144d0b914
        http://127.0.0.1:8888/tree?token=9f276798b6fd05f2f04663f6639d67d49bdbbec144d0b914
[I 2025-03-11 00:28:45.151 ServerApp] Skipped non-installed server(s): bash-language-server, dockerfile-language-server-nodejs, javascript-typescript-langserver, jedi-language-server, julia-language-server, pyright, python-language-server, python-lsp-server, r-languageserver, sql-language-server, texlab, typescript-language-server, unified-language-server, vscode-css-languageserver-bin, vscode-html-languageserver-bin, vscode-json-languageserver-bin, yaml-language-server
[W 2025-03-11 00:45:10.299 ServerApp] 404 GET /hub/api (@127.0.0.1) 10.05ms referer=None
[I 2025-03-11 00:45:10.301 ServerApp] 302 GET / (@127.0.0.1) 0.22ms
[I 2025-03-11 00:45:10.303 JupyterNotebookApp] 302 GET /tree? (@127.0.0.1) 0.33ms
[W 2025-03-11 00:45:26.645 ServerApp] 401 POST /login? (@127.0.0.1) 0.59ms referer=None
[W 2025-03-11 00:45:26.649 ServerApp] wrote error: 'Forbidden'
    Traceback (most recent call last):
      File "/home/cbel/Desktop/YIHAN/venv/lib/python3.8/site-packages/tornado/web.py", line 1788, in _execute
        result = method(*self.path_args, **self.path_kwargs)
      File "/home/cbel/Desktop/YIHAN/venv/lib/python3.8/site-packages/tornado/web.py", line 3289, in wrapper
        url = self.get_login_url()
      File "/home/cbel/Desktop/YIHAN/venv/lib/python3.8/site-packages/jupyter_server/base/handlers.py", line 783, in get_login_url
        raise web.HTTPError(403)
    tornado.web.HTTPError: HTTP 403: Forbidden
[W 2025-03-11 00:45:26.650 ServerApp] 403 GET /api/kernelspecs?1741625126647 (@127.0.0.1) 1.04ms referer=None
[W 2025-03-11 00:45:26.650 ServerApp] wrote error: 'Forbidden'
    Traceback (most recent call last):
      File "/home/cbel/Desktop/YIHAN/venv/lib/python3.8/site-packages/tornado/web.py", line 1788, in _execute
        result = method(*self.path_args, **self.path_kwargs)
      File "/home/cbel/Desktop/YIHAN/venv/lib/python3.8/site-packages/tornado/web.py", line 3289, in wrapper
        url = self.get_login_url()
      File "/home/cbel/Desktop/YIHAN/venv/lib/python3.8/site-packages/jupyter_server/base/handlers.py", line 783, in get_login_url
        raise web.HTTPError(403)
    tornado.web.HTTPError: HTTP 403: Forbidden
[W 2025-03-11 00:45:26.651 ServerApp] 403 GET /api/kernels?1741625126648 (@127.0.0.1) 0.47ms referer=None
[W 2025-03-11 00:45:26.652 ServerApp] wrote error: 'Forbidden'
    Traceback (most recent call last):
      File "/home/cbel/Desktop/YIHAN/venv/lib/python3.8/site-packages/tornado/web.py", line 1788, in _execute
        result = method(*self.path_args, **self.path_kwargs)
      File "/home/cbel/Desktop/YIHAN/venv/lib/python3.8/site-packages/tornado/web.py", line 3289, in wrapper
        url = self.get_login_url()
      File "/home/cbel/Desktop/YIHAN/venv/lib/python3.8/site-packages/jupyter_server/base/handlers.py", line 783, in get_login_url
        raise web.HTTPError(403)
    tornado.web.HTTPError: HTTP 403: Forbidden
[W 2025-03-11 00:45:26.652 ServerApp] 403 GET /api/kernels?1741625126649 (@127.0.0.1) 0.60ms referer=None
[W 2025-03-11 00:45:26.652 ServerApp] wrote error: 'Forbidden'
    Traceback (most recent call last):
      File "/home/cbel/Desktop/YIHAN/venv/lib/python3.8/site-packages/tornado/web.py", line 1788, in _execute
        result = method(*self.path_args, **self.path_kwargs)
      File "/home/cbel/Desktop/YIHAN/venv/lib/python3.8/site-packages/tornado/web.py", line 3289, in wrapper
        url = self.get_login_url()
      File "/home/cbel/Desktop/YIHAN/venv/lib/python3.8/site-packages/jupyter_server/base/handlers.py", line 783, in get_login_url
        raise web.HTTPError(403)
    tornado.web.HTTPError: HTTP 403: Forbidden
[W 2025-03-11 00:45:26.652 ServerApp] 403 GET /api/sessions?1741625126650 (@127.0.0.1) 0.88ms referer=None
[W 2025-03-11 00:45:26.657 ServerApp] 404 GET /hub/api (@127.0.0.1) 0.75ms referer=None
[W 2025-03-11 00:45:26.657 ServerApp] wrote error: 'Forbidden'
    Traceback (most recent call last):
      File "/home/cbel/Desktop/YIHAN/venv/lib/python3.8/site-packages/tornado/web.py", line 1788, in _execute
        result = method(*self.path_args, **self.path_kwargs)
      File "/home/cbel/Desktop/YIHAN/venv/lib/python3.8/site-packages/tornado/web.py", line 3289, in wrapper
        url = self.get_login_url()
      File "/home/cbel/Desktop/YIHAN/venv/lib/python3.8/site-packages/jupyter_server/base/handlers.py", line 783, in get_login_url
        raise web.HTTPError(403)
    tornado.web.HTTPError: HTTP 403: Forbidden
[W 2025-03-11 00:45:26.657 ServerApp] 403 GET /api/kernelspecs?1741625126654 (@127.0.0.1) 1.02ms referer=None
[I 2025-03-11 00:45:26.658 ServerApp] 302 GET / (@127.0.0.1) 0.19ms
[I 2025-03-11 00:45:26.660 JupyterNotebookApp] 302 GET /tree? (@127.0.0.1) 0.29ms
[C 2025-03-11 00:47:53.189 ServerApp] received signal 15, stopping
[I 2025-03-11 00:47:53.191 ServerApp] Shutting down 5 extensions
Fail to get yarn configuration. /home/cbel/Desktop/YIHAN/venv/lib/python3.8/site-packages/jupyterlab/staging/yarn.js:4
(()=>{var Qge=Object.create;var AS=Object.defineProperty;var bge=Object.getOwnPropertyDescriptor;var Sge=Object.getOwnPropertyNames;var vge=Object.getPrototypeOf,xge=Object.prototype.hasOwnProperty;var J=(r=>typeof require<"u"?require:typeof Proxy<"u"?new Proxy(r,{get:(e,t)=>(typeof require<"u"?require:e)[t]}):r)(function(r){if(typeof require<"u")return require.apply(this,arguments);throw new Error('Dynamic require of "'+r+'" is not supported')});var Pge=(r,e)=>()=>(r&&(e=r(r=0)),e);var w=(r,e)=>()=>(e||r((e={exports:{}}).exports,e),e.exports),ut=(r,e)=>{for(var t in e)AS(r,t,{get:e[t],enumerable:!0})},Dge=(r,e,t,i)=>{if(e&&typeof e=="object"||typeof e=="function")for(let n of Sge(e))!xge.call(r,n)&&n!==t&&AS(r,n,{get:()=>e[n],enumerable:!(i=bge(e,n))||i.enumerable});return r};var Pe=(r,e,t)=>(t=r!=null?Qge(vge(r)):{},Dge(e||!r||!r.__esModule?AS(t,"default",{value:r,enumerable:!0}):t,r));var QK=w((GXe,BK)=>{BK.exports=wK;

SyntaxError: Unexpected token {
    at createScript (vm.js:80:10)
    at Object.runInThisContext (vm.js:139:10)
    at Module._compile (module.js:616:28)
    at Object.Module._extensions..js (module.js:663:10)
    at Module.load (module.js:565:32)
    at tryModuleLoad (module.js:505:12)
    at Function.Module._load (module.js:497:3)
    at Function.Module.runMain (module.js:693:10)
    at startup (bootstrap_node.js:188:16)
    at bootstrap_node.js:609:3

[I 2025-03-11 00:50:18.991 ServerApp] jupyter_lsp | extension was successfully linked.
[I 2025-03-11 00:50:18.994 ServerApp] jupyter_server_terminals | extension was successfully linked.
[I 2025-03-11 00:50:18.997 ServerApp] jupyterlab | extension was successfully linked.
[I 2025-03-11 00:50:19.000 ServerApp] notebook | extension was successfully linked.
[I 2025-03-11 00:50:19.116 ServerApp] notebook_shim | extension was successfully linked.
[I 2025-03-11 00:50:19.156 ServerApp] notebook_shim | extension was successfully loaded.
[I 2025-03-11 00:50:19.157 ServerApp] jupyter_lsp | extension was successfully loaded.
[I 2025-03-11 00:50:19.158 ServerApp] jupyter_server_terminals | extension was successfully loaded.
[I 2025-03-11 00:50:19.159 LabApp] JupyterLab extension loaded from /home/cbel/Desktop/YIHAN/venv/lib/python3.8/site-packages/jupyterlab
[I 2025-03-11 00:50:19.159 LabApp] JupyterLab application directory is /home/cbel/Desktop/YIHAN/venv/share/jupyter/lab
[I 2025-03-11 00:50:19.159 LabApp] Extension Manager is 'pypi'.
[I 2025-03-11 00:50:19.176 ServerApp] jupyterlab | extension was successfully loaded.
[I 2025-03-11 00:50:19.178 ServerApp] notebook | extension was successfully loaded.
[I 2025-03-11 00:50:19.179 ServerApp] Serving notebooks from local directory: /home/cbel/Desktop/YIHAN/unet
[I 2025-03-11 00:50:19.179 ServerApp] Jupyter Server 2.14.2 is running at:
[I 2025-03-11 00:50:19.179 ServerApp] http://localhost:8888/tree?token=f554aa01734dcd0b0be6163dced349074ff6153d20e82bdf
[I 2025-03-11 00:50:19.179 ServerApp]     http://127.0.0.1:8888/tree?token=f554aa01734dcd0b0be6163dced349074ff6153d20e82bdf
[I 2025-03-11 00:50:19.179 ServerApp] Use Control-C to stop this server and shut down all kernels (twice to skip confirmation).
[C 2025-03-11 00:50:19.180 ServerApp] 
    
    To access the server, open this file in a browser:
        file:///home/cbel/.local/share/jupyter/runtime/jpserver-7069-open.html
    Or copy and paste one of these URLs:
        http://localhost:8888/tree?token=f554aa01734dcd0b0be6163dced349074ff6153d20e82bdf
        http://127.0.0.1:8888/tree?token=f554aa01734dcd0b0be6163dced349074ff6153d20e82bdf
[I 2025-03-11 00:50:19.515 ServerApp] Skipped non-installed server(s): bash-language-server, dockerfile-language-server-nodejs, javascript-typescript-langserver, jedi-language-server, julia-language-server, pyright, python-language-server, python-lsp-server, r-languageserver, sql-language-server, texlab, typescript-language-server, unified-language-server, vscode-css-languageserver-bin, vscode-html-languageserver-bin, vscode-json-languageserver-bin, yaml-language-server
[W 2025-03-11 00:52:10.969 ServerApp] 404 GET /hub/api (@127.0.0.1) 12.21ms referer=None
[I 2025-03-11 00:52:10.970 ServerApp] 302 GET / (@127.0.0.1) 0.22ms
[I 2025-03-11 00:52:10.971 JupyterNotebookApp] 302 GET /tree? (@127.0.0.1) 0.33ms
[I 2025-03-11 00:52:20.728 ServerApp] User bff5b615b982451093a8f0d7a8f409cf logged in.
[I 2025-03-11 00:52:20.729 ServerApp] 302 POST /login? (bff5b615b982451093a8f0d7a8f409cf@127.0.0.1) 3.27ms
[I 2025-03-11 00:54:52.359 ServerApp] Kernel started: 1de8e015-989c-4517-9652-22e55ae10bab
[I 2025-03-11 00:54:52.719 ServerApp] Connecting to kernel 1de8e015-989c-4517-9652-22e55ae10bab.
2025-03-11 00:54:54.034457: I tensorflow/stream_executor/cuda/cuda_gpu_executor.cc:939] successful NUMA node read from SysFS had negative value (-1), but there must be at least one NUMA node, so returning NUMA node zero
2025-03-11 00:54:54.038939: I tensorflow/stream_executor/cuda/cuda_gpu_executor.cc:939] successful NUMA node read from SysFS had negative value (-1), but there must be at least one NUMA node, so returning NUMA node zero
2025-03-11 00:54:54.039420: I tensorflow/stream_executor/cuda/cuda_gpu_executor.cc:939] successful NUMA node read from SysFS had negative value (-1), but there must be at least one NUMA node, so returning NUMA node zero
2025-03-11 00:54:57.548870: I tensorflow/core/platform/cpu_feature_guard.cc:151] This TensorFlow binary is optimized with oneAPI Deep Neural Network Library (oneDNN) to use the following CPU instructions in performance-critical operations:  AVX2 FMA
To enable them in other operations, rebuild TensorFlow with the appropriate compiler flags.
2025-03-11 00:54:57.549501: I tensorflow/stream_executor/cuda/cuda_gpu_executor.cc:939] successful NUMA node read from SysFS had negative value (-1), but there must be at least one NUMA node, so returning NUMA node zero
2025-03-11 00:54:57.550338: I tensorflow/stream_executor/cuda/cuda_gpu_executor.cc:939] successful NUMA node read from SysFS had negative value (-1), but there must be at least one NUMA node, so returning NUMA node zero
2025-03-11 00:54:57.551052: I tensorflow/stream_executor/cuda/cuda_gpu_executor.cc:939] successful NUMA node read from SysFS had negative value (-1), but there must be at least one NUMA node, so returning NUMA node zero
2025-03-11 00:54:57.894727: I tensorflow/stream_executor/cuda/cuda_gpu_executor.cc:939] successful NUMA node read from SysFS had negative value (-1), but there must be at least one NUMA node, so returning NUMA node zero
2025-03-11 00:54:57.895250: I tensorflow/stream_executor/cuda/cuda_gpu_executor.cc:939] successful NUMA node read from SysFS had negative value (-1), but there must be at least one NUMA node, so returning NUMA node zero
2025-03-11 00:54:57.895710: I tensorflow/stream_executor/cuda/cuda_gpu_executor.cc:939] successful NUMA node read from SysFS had negative value (-1), but there must be at least one NUMA node, so returning NUMA node zero
2025-03-11 00:54:57.896144: I tensorflow/core/common_runtime/gpu/gpu_process_state.cc:214] Using CUDA malloc Async allocator for GPU: 0
2025-03-11 00:54:57.896578: I tensorflow/core/common_runtime/gpu/gpu_device.cc:1525] Created device /job:localhost/replica:0/task:0/device:GPU:0 with 12288 MB memory:  -> device: 0, name: NVIDIA GeForce RTX 3090, pci bus id: 0000:01:00.0, compute capability: 8.6
2025-03-11 00:55:22.839236: I tensorflow/stream_executor/cuda/cuda_gpu_executor.cc:939] successful NUMA node read from SysFS had negative value (-1), but there must be at least one NUMA node, so returning NUMA node zero
2025-03-11 00:55:39.690911: I tensorflow/stream_executor/cuda/cuda_dnn.cc:366] Loaded cuDNN version 8202
[I 2025-03-11 06:49:25.150 ServerApp] Starting buffering for 1de8e015-989c-4517-9652-22e55ae10bab:bb5da35c-7060-4bac-89d4-c6812122499e
[I 2025-03-11 09:08:17.145 ServerApp] 302 GET / (@127.0.0.1) 0.32ms
[I 2025-03-11 09:08:17.154 JupyterNotebookApp] 302 GET /tree? (@127.0.0.1) 0.55ms
[I 2025-03-11 09:13:40.740 ServerApp] User 30d25a1301a34f2399e0190fbfbe1a3d logged in.
[I 2025-03-11 09:13:40.740 ServerApp] 302 POST /login? (30d25a1301a34f2399e0190fbfbe1a3d@127.0.0.1) 0.67ms
[I 2025-03-11 09:13:40.778 ServerApp] Connecting to kernel 1de8e015-989c-4517-9652-22e55ae10bab.
[I 2025-03-11 09:13:40.778 ServerApp] Discarding 12923 buffered messages for 1de8e015-989c-4517-9652-22e55ae10bab:bb5da35c-7060-4bac-89d4-c6812122499e
[I 2025-03-11 09:48:57.208 ServerApp] 302 GET / (@127.0.0.1) 0.35ms
[I 2025-03-11 09:48:57.215 JupyterNotebookApp] 302 GET /tree? (@127.0.0.1) 0.45ms
[I 2025-03-11 09:49:22.606 ServerApp] User 19a97b06aef2463fbbc9063c6c96c752 logged in.
[I 2025-03-11 09:49:22.606 ServerApp] 302 POST /login? (19a97b06aef2463fbbc9063c6c96c752@127.0.0.1) 0.70ms
[I 2025-03-11 09:49:22.638 ServerApp] Connecting to kernel 1de8e015-989c-4517-9652-22e55ae10bab.
[I 2025-03-11 13:38:52.650 ServerApp] 302 GET / (@127.0.0.1) 0.24ms
[I 2025-03-11 13:38:52.653 JupyterNotebookApp] 302 GET /tree? (@127.0.0.1) 0.31ms
[I 2025-03-11 13:39:07.885 ServerApp] User 22f3bbd745974a1983c72e3a75b3d9bb logged in.
[I 2025-03-11 13:39:07.885 ServerApp] 302 POST /login? (22f3bbd745974a1983c72e3a75b3d9bb@127.0.0.1) 0.80ms
[I 2025-03-11 13:39:07.931 ServerApp] Connecting to kernel 1de8e015-989c-4517-9652-22e55ae10bab.
[I 2025-03-11 14:49:17.758 ServerApp] 302 GET / (@127.0.0.1) 0.40ms
[I 2025-03-11 14:49:17.762 JupyterNotebookApp] 302 GET /tree? (@127.0.0.1) 0.51ms
[I 2025-03-11 14:49:20.130 ServerApp] User 33bba1d7d9dd43499beed71bda4ea8be logged in.
[I 2025-03-11 14:49:20.130 ServerApp] 302 POST /login? (33bba1d7d9dd43499beed71bda4ea8be@127.0.0.1) 0.77ms
[I 2025-03-11 14:49:20.209 ServerApp] Connecting to kernel 1de8e015-989c-4517-9652-22e55ae10bab.
[I 2025-03-11 17:00:40.274 ServerApp] Starting buffering for 1de8e015-989c-4517-9652-22e55ae10bab:9fa68e71-b93e-4dd9-b1c3-f9e662d6a86d
[I 2025-03-11 17:01:12.634 ServerApp] 302 GET / (@127.0.0.1) 0.40ms
[I 2025-03-11 17:01:12.639 JupyterNotebookApp] 302 GET /tree? (@127.0.0.1) 0.51ms
[I 2025-03-11 17:01:16.953 ServerApp] User b19d2d58b977450fbc0c738ae438cc2a logged in.
[I 2025-03-11 17:01:16.953 ServerApp] 302 POST /login? (b19d2d58b977450fbc0c738ae438cc2a@127.0.0.1) 0.66ms
[I 2025-03-11 17:01:16.997 ServerApp] Connecting to kernel 1de8e015-989c-4517-9652-22e55ae10bab.
[I 2025-03-11 17:01:49.630 ServerApp] Kernel interrupted: 1de8e015-989c-4517-9652-22e55ae10bab
[I 2025-03-11 23:44:10.217 ServerApp] Kernel interrupted: 1de8e015-989c-4517-9652-22e55ae10bab
[I 2025-03-11 23:47:12.041 ServerApp] 302 GET / (@127.0.0.1) 0.26ms
[I 2025-03-11 23:47:12.044 JupyterNotebookApp] 302 GET /tree? (@127.0.0.1) 0.33ms
[I 2025-03-11 23:48:19.450 ServerApp] User 9ec7cbe9a2e747d3a0fe0ea6c2647cd2 logged in.
[I 2025-03-11 23:48:19.451 ServerApp] 302 POST /login? (9ec7cbe9a2e747d3a0fe0ea6c2647cd2@127.0.0.1) 0.65ms
[I 2025-03-11 23:48:19.485 ServerApp] Connecting to kernel 1de8e015-989c-4517-9652-22e55ae10bab.
[I 2025-03-12 07:03:12.319 ServerApp] Starting buffering for 1de8e015-989c-4517-9652-22e55ae10bab:71b39151-e76c-4402-9aa3-ff4310df4c3b
[I 2025-03-12 08:44:08.627 ServerApp] 302 GET / (@127.0.0.1) 0.29ms
[I 2025-03-12 08:44:08.632 JupyterNotebookApp] 302 GET /tree? (@127.0.0.1) 0.35ms
[I 2025-03-12 08:44:18.956 ServerApp] User 4273db01d99447ab9ede71967d42b576 logged in.
[I 2025-03-12 08:44:18.956 ServerApp] 302 POST /login? (4273db01d99447ab9ede71967d42b576@127.0.0.1) 0.57ms
[I 2025-03-12 08:44:18.985 ServerApp] Connecting to kernel 1de8e015-989c-4517-9652-22e55ae10bab.
[I 2025-03-12 08:45:05.428 ServerApp] Kernel interrupted: 1de8e015-989c-4517-9652-22e55ae10bab
[I 2025-03-12 16:00:58.864 ServerApp] Starting buffering for 1de8e015-989c-4517-9652-22e55ae10bab:ed7382fe-08d8-4d68-b190-2d0e07deedea
[I 2025-03-12 22:04:16.312 ServerApp] 302 GET / (@127.0.0.1) 0.27ms
[I 2025-03-12 22:04:16.314 JupyterNotebookApp] 302 GET /tree? (@127.0.0.1) 0.36ms
[I 2025-03-12 22:04:17.781 ServerApp] User 082898f272544b2f8e7e033a70d895bc logged in.
[I 2025-03-12 22:04:17.781 ServerApp] 302 POST /login? (082898f272544b2f8e7e033a70d895bc@127.0.0.1) 0.56ms
[I 2025-03-12 22:04:17.812 ServerApp] Connecting to kernel 1de8e015-989c-4517-9652-22e55ae10bab.
Fail to get yarn configuration. /home/cbel/Desktop/YIHAN/venv/lib/python3.8/site-packages/jupyterlab/staging/yarn.js:4
(()=>{var Qge=Object.create;var AS=Object.defineProperty;var bge=Object.getOwnPropertyDescriptor;var Sge=Object.getOwnPropertyNames;var vge=Object.getPrototypeOf,xge=Object.prototype.hasOwnProperty;var J=(r=>typeof require<"u"?require:typeof Proxy<"u"?new Proxy(r,{get:(e,t)=>(typeof require<"u"?require:e)[t]}):r)(function(r){if(typeof require<"u")return require.apply(this,arguments);throw new Error('Dynamic require of "'+r+'" is not supported')});var Pge=(r,e)=>()=>(r&&(e=r(r=0)),e);var w=(r,e)=>()=>(e||r((e={exports:{}}).exports,e),e.exports),ut=(r,e)=>{for(var t in e)AS(r,t,{get:e[t],enumerable:!0})},Dge=(r,e,t,i)=>{if(e&&typeof e=="object"||typeof e=="function")for(let n of Sge(e))!xge.call(r,n)&&n!==t&&AS(r,n,{get:()=>e[n],enumerable:!(i=bge(e,n))||i.enumerable});return r};var Pe=(r,e,t)=>(t=r!=null?Qge(vge(r)):{},Dge(e||!r||!r.__esModule?AS(t,"default",{value:r,enumerable:!0}):t,r));var QK=w((GXe,BK)=>{BK.exports=wK;

SyntaxError: Unexpected token {
    at createScript (vm.js:80:10)
    at Object.runInThisContext (vm.js:139:10)
    at Module._compile (module.js:616:28)
    at Object.Module._extensions..js (module.js:663:10)
    at Module.load (module.js:565:32)
    at tryModuleLoad (module.js:505:12)
    at Function.Module._load (module.js:497:3)
    at Function.Module.runMain (module.js:693:10)
    at startup (bootstrap_node.js:188:16)
    at bootstrap_node.js:609:3

[I 2025-03-19 22:26:16.312 ServerApp] jupyter_lsp | extension was successfully linked.
[I 2025-03-19 22:26:16.315 ServerApp] jupyter_server_terminals | extension was successfully linked.
[I 2025-03-19 22:26:16.318 ServerApp] jupyterlab | extension was successfully linked.
[I 2025-03-19 22:26:16.321 ServerApp] notebook | extension was successfully linked.
[I 2025-03-19 22:26:16.435 ServerApp] notebook_shim | extension was successfully linked.
[I 2025-03-19 22:26:16.479 ServerApp] notebook_shim | extension was successfully loaded.
[I 2025-03-19 22:26:16.480 ServerApp] jupyter_lsp | extension was successfully loaded.
[I 2025-03-19 22:26:16.481 ServerApp] jupyter_server_terminals | extension was successfully loaded.
[I 2025-03-19 22:26:16.483 LabApp] JupyterLab extension loaded from /home/cbel/Desktop/YIHAN/venv/lib/python3.8/site-packages/jupyterlab
[I 2025-03-19 22:26:16.483 LabApp] JupyterLab application directory is /home/cbel/Desktop/YIHAN/venv/share/jupyter/lab
[I 2025-03-19 22:26:16.483 LabApp] Extension Manager is 'pypi'.
[I 2025-03-19 22:26:16.506 ServerApp] jupyterlab | extension was successfully loaded.
[I 2025-03-19 22:26:16.508 ServerApp] notebook | extension was successfully loaded.
[I 2025-03-19 22:26:16.508 ServerApp] Serving notebooks from local directory: /home/cbel/Desktop/YIHAN/unet
[I 2025-03-19 22:26:16.508 ServerApp] Jupyter Server 2.14.2 is running at:
[I 2025-03-19 22:26:16.508 ServerApp] http://localhost:8888/tree?token=03218368e59344420e09a6b421cbf5331bfae3430e53fb25
[I 2025-03-19 22:26:16.508 ServerApp]     http://127.0.0.1:8888/tree?token=03218368e59344420e09a6b421cbf5331bfae3430e53fb25
[I 2025-03-19 22:26:16.508 ServerApp] Use Control-C to stop this server and shut down all kernels (twice to skip confirmation).
[W 2025-03-19 22:26:16.511 ServerApp] No web browser found: Error('could not locate runnable browser').
[C 2025-03-19 22:26:16.511 ServerApp] 
    
    To access the server, open this file in a browser:
        file:///home/cbel/.local/share/jupyter/runtime/jpserver-8616-open.html
    Or copy and paste one of these URLs:
        http://localhost:8888/tree?token=03218368e59344420e09a6b421cbf5331bfae3430e53fb25
        http://127.0.0.1:8888/tree?token=03218368e59344420e09a6b421cbf5331bfae3430e53fb25
[I 2025-03-19 22:26:16.905 ServerApp] Skipped non-installed server(s): bash-language-server, dockerfile-language-server-nodejs, javascript-typescript-langserver, jedi-language-server, julia-language-server, pyright, python-language-server, python-lsp-server, r-languageserver, sql-language-server, texlab, typescript-language-server, unified-language-server, vscode-css-languageserver-bin, vscode-html-languageserver-bin, vscode-json-languageserver-bin, yaml-language-server
[W 2025-03-19 22:27:06.868 ServerApp] 404 GET /hub/api (@127.0.0.1) 11.09ms referer=None
[I 2025-03-19 22:27:06.870 ServerApp] 302 GET / (@127.0.0.1) 0.23ms
[I 2025-03-19 22:27:06.871 JupyterNotebookApp] 302 GET /tree? (@127.0.0.1) 0.33ms
[I 2025-03-19 22:27:14.511 ServerApp] User 5fd66b9d0f2b4341970b5283c0cf3af5 logged in.
[I 2025-03-19 22:27:14.511 ServerApp] 302 POST /login? (5fd66b9d0f2b4341970b5283c0cf3af5@127.0.0.1) 0.86ms
[W 2025-03-19 22:28:04.318 ServerApp] 404 GET /hub/api (@127.0.0.1) 3.31ms referer=None
[I 2025-03-19 22:28:04.320 ServerApp] 302 GET / (@127.0.0.1) 0.20ms
[I 2025-03-19 22:28:04.321 JupyterNotebookApp] 302 GET /tree? (@127.0.0.1) 0.30ms
[I 2025-03-19 22:28:10.229 ServerApp] User dd633bc80dbd4173a4132cbb4d0511d4 logged in.
[I 2025-03-19 22:28:10.230 ServerApp] 302 POST /login? (dd633bc80dbd4173a4132cbb4d0511d4@127.0.0.1) 0.91ms
[I 2025-03-19 22:28:49.718 ServerApp] Kernel started: c2f5cbbe-5426-4551-b160-3a95988a0bb2
[I 2025-03-19 22:28:50.078 ServerApp] Connecting to kernel c2f5cbbe-5426-4551-b160-3a95988a0bb2.
2025-03-19 22:28:52.283026: I tensorflow/stream_executor/cuda/cuda_gpu_executor.cc:939] successful NUMA node read from SysFS had negative value (-1), but there must be at least one NUMA node, so returning NUMA node zero
2025-03-19 22:28:52.308381: I tensorflow/stream_executor/cuda/cuda_gpu_executor.cc:939] successful NUMA node read from SysFS had negative value (-1), but there must be at least one NUMA node, so returning NUMA node zero
2025-03-19 22:28:52.308902: I tensorflow/stream_executor/cuda/cuda_gpu_executor.cc:939] successful NUMA node read from SysFS had negative value (-1), but there must be at least one NUMA node, so returning NUMA node zero
2025-03-19 22:28:52.329550: I tensorflow/core/platform/cpu_feature_guard.cc:151] This TensorFlow binary is optimized with oneAPI Deep Neural Network Library (oneDNN) to use the following CPU instructions in performance-critical operations:  AVX2 FMA
To enable them in other operations, rebuild TensorFlow with the appropriate compiler flags.
2025-03-19 22:28:52.330361: I tensorflow/stream_executor/cuda/cuda_gpu_executor.cc:939] successful NUMA node read from SysFS had negative value (-1), but there must be at least one NUMA node, so returning NUMA node zero
2025-03-19 22:28:52.330960: I tensorflow/stream_executor/cuda/cuda_gpu_executor.cc:939] successful NUMA node read from SysFS had negative value (-1), but there must be at least one NUMA node, so returning NUMA node zero
2025-03-19 22:28:52.331427: I tensorflow/stream_executor/cuda/cuda_gpu_executor.cc:939] successful NUMA node read from SysFS had negative value (-1), but there must be at least one NUMA node, so returning NUMA node zero
2025-03-19 22:28:52.867262: I tensorflow/stream_executor/cuda/cuda_gpu_executor.cc:939] successful NUMA node read from SysFS had negative value (-1), but there must be at least one NUMA node, so returning NUMA node zero
2025-03-19 22:28:52.867762: I tensorflow/stream_executor/cuda/cuda_gpu_executor.cc:939] successful NUMA node read from SysFS had negative value (-1), but there must be at least one NUMA node, so returning NUMA node zero
2025-03-19 22:28:52.868210: I tensorflow/stream_executor/cuda/cuda_gpu_executor.cc:939] successful NUMA node read from SysFS had negative value (-1), but there must be at least one NUMA node, so returning NUMA node zero
2025-03-19 22:28:52.868638: I tensorflow/core/common_runtime/gpu/gpu_process_state.cc:214] Using CUDA malloc Async allocator for GPU: 0
2025-03-19 22:28:52.869270: I tensorflow/core/common_runtime/gpu/gpu_device.cc:1525] Created device /job:localhost/replica:0/task:0/device:GPU:0 with 18432 MB memory:  -> device: 0, name: NVIDIA GeForce RTX 3090, pci bus id: 0000:01:00.0, compute capability: 8.6
[I 2025-03-19 22:32:16.709 ServerApp] AsyncIOLoopKernelRestarter: restarting kernel (1/5), keep random ports
[W 2025-03-19 22:32:16.711 ServerApp] kernel c2f5cbbe-5426-4551-b160-3a95988a0bb2 restarted
[I 2025-03-19 22:32:16.745 ServerApp] Starting buffering for c2f5cbbe-5426-4551-b160-3a95988a0bb2:d87b9f7c-7ee5-4ab2-b309-167031d62f9c
[I 2025-03-19 22:32:16.766 ServerApp] Connecting to kernel c2f5cbbe-5426-4551-b160-3a95988a0bb2.
[I 2025-03-19 22:32:16.766 ServerApp] Restoring connection for c2f5cbbe-5426-4551-b160-3a95988a0bb2:d87b9f7c-7ee5-4ab2-b309-167031d62f9c
[I 2025-03-19 22:33:25.418 ServerApp] Kernel restarted: c2f5cbbe-5426-4551-b160-3a95988a0bb2
[I 2025-03-19 22:33:25.420 ServerApp] Starting buffering for c2f5cbbe-5426-4551-b160-3a95988a0bb2:d87b9f7c-7ee5-4ab2-b309-167031d62f9c
[I 2025-03-19 22:33:25.423 ServerApp] Connecting to kernel c2f5cbbe-5426-4551-b160-3a95988a0bb2.
[I 2025-03-19 22:33:25.423 ServerApp] Restoring connection for c2f5cbbe-5426-4551-b160-3a95988a0bb2:d87b9f7c-7ee5-4ab2-b309-167031d62f9c
2025-03-19 22:33:33.618395: I tensorflow/stream_executor/cuda/cuda_gpu_executor.cc:939] successful NUMA node read from SysFS had negative value (-1), but there must be at least one NUMA node, so returning NUMA node zero
2025-03-19 22:33:33.667040: I tensorflow/stream_executor/cuda/cuda_gpu_executor.cc:939] successful NUMA node read from SysFS had negative value (-1), but there must be at least one NUMA node, so returning NUMA node zero
2025-03-19 22:33:33.669678: I tensorflow/stream_executor/cuda/cuda_gpu_executor.cc:939] successful NUMA node read from SysFS had negative value (-1), but there must be at least one NUMA node, so returning NUMA node zero
2025-03-19 22:33:33.688622: I tensorflow/core/platform/cpu_feature_guard.cc:151] This TensorFlow binary is optimized with oneAPI Deep Neural Network Library (oneDNN) to use the following CPU instructions in performance-critical operations:  AVX2 FMA
To enable them in other operations, rebuild TensorFlow with the appropriate compiler flags.
2025-03-19 22:33:33.689735: I tensorflow/stream_executor/cuda/cuda_gpu_executor.cc:939] successful NUMA node read from SysFS had negative value (-1), but there must be at least one NUMA node, so returning NUMA node zero
2025-03-19 22:33:33.690708: I tensorflow/stream_executor/cuda/cuda_gpu_executor.cc:939] successful NUMA node read from SysFS had negative value (-1), but there must be at least one NUMA node, so returning NUMA node zero
2025-03-19 22:33:33.691464: I tensorflow/stream_executor/cuda/cuda_gpu_executor.cc:939] successful NUMA node read from SysFS had negative value (-1), but there must be at least one NUMA node, so returning NUMA node zero
2025-03-19 22:33:34.324066: I tensorflow/stream_executor/cuda/cuda_gpu_executor.cc:939] successful NUMA node read from SysFS had negative value (-1), but there must be at least one NUMA node, so returning NUMA node zero
2025-03-19 22:33:34.324559: I tensorflow/stream_executor/cuda/cuda_gpu_executor.cc:939] successful NUMA node read from SysFS had negative value (-1), but there must be at least one NUMA node, so returning NUMA node zero
2025-03-19 22:33:34.325006: I tensorflow/stream_executor/cuda/cuda_gpu_executor.cc:939] successful NUMA node read from SysFS had negative value (-1), but there must be at least one NUMA node, so returning NUMA node zero
2025-03-19 22:33:34.325431: I tensorflow/core/common_runtime/gpu/gpu_process_state.cc:214] Using CUDA malloc Async allocator for GPU: 0
2025-03-19 22:33:34.326053: I tensorflow/core/common_runtime/gpu/gpu_device.cc:1525] Created device /job:localhost/replica:0/task:0/device:GPU:0 with 18432 MB memory:  -> device: 0, name: NVIDIA GeForce RTX 3090, pci bus id: 0000:01:00.0, compute capability: 8.6
[I 2025-03-19 22:37:13.410 ServerApp] AsyncIOLoopKernelRestarter: restarting kernel (1/5), keep random ports
[W 2025-03-19 22:37:13.411 ServerApp] kernel c2f5cbbe-5426-4551-b160-3a95988a0bb2 restarted
[I 2025-03-19 22:37:13.446 ServerApp] Starting buffering for c2f5cbbe-5426-4551-b160-3a95988a0bb2:d87b9f7c-7ee5-4ab2-b309-167031d62f9c
[I 2025-03-19 22:37:13.475 ServerApp] Connecting to kernel c2f5cbbe-5426-4551-b160-3a95988a0bb2.
[I 2025-03-19 22:37:13.475 ServerApp] Restoring connection for c2f5cbbe-5426-4551-b160-3a95988a0bb2:d87b9f7c-7ee5-4ab2-b309-167031d62f9c
[I 2025-03-19 22:37:45.584 ServerApp] Starting buffering for c2f5cbbe-5426-4551-b160-3a95988a0bb2:d87b9f7c-7ee5-4ab2-b309-167031d62f9c
[I 2025-03-19 22:38:22.157 ServerApp] 302 GET / (@127.0.0.1) 0.27ms
[I 2025-03-19 22:38:22.158 ServerApp] 302 GET / (@127.0.0.1) 0.21ms
[I 2025-03-19 22:38:22.161 JupyterNotebookApp] 302 GET /tree? (@127.0.0.1) 0.37ms
[I 2025-03-19 22:38:22.162 JupyterNotebookApp] 302 GET /tree? (@127.0.0.1) 0.33ms
[W 2025-03-19 22:38:22.938 ServerApp] wrote error: 'Forbidden'
    Traceback (most recent call last):
      File "/home/cbel/Desktop/YIHAN/venv/lib/python3.8/site-packages/tornado/web.py", line 1788, in _execute
        result = method(*self.path_args, **self.path_kwargs)
      File "/home/cbel/Desktop/YIHAN/venv/lib/python3.8/site-packages/tornado/web.py", line 3289, in wrapper
        url = self.get_login_url()
      File "/home/cbel/Desktop/YIHAN/venv/lib/python3.8/site-packages/jupyter_server/base/handlers.py", line 783, in get_login_url
        raise web.HTTPError(403)
    tornado.web.HTTPError: HTTP 403: Forbidden
[W 2025-03-19 22:38:22.940 ServerApp] 403 GET /api/kernelspecs?1742395102935 (@127.0.0.1) 2.01ms referer=None
[W 2025-03-19 22:38:22.941 ServerApp] wrote error: 'Forbidden'
    Traceback (most recent call last):
      File "/home/cbel/Desktop/YIHAN/venv/lib/python3.8/site-packages/tornado/web.py", line 1788, in _execute
        result = method(*self.path_args, **self.path_kwargs)
      File "/home/cbel/Desktop/YIHAN/venv/lib/python3.8/site-packages/tornado/web.py", line 3289, in wrapper
        url = self.get_login_url()
      File "/home/cbel/Desktop/YIHAN/venv/lib/python3.8/site-packages/jupyter_server/base/handlers.py", line 783, in get_login_url
        raise web.HTTPError(403)
    tornado.web.HTTPError: HTTP 403: Forbidden
[W 2025-03-19 22:38:22.941 ServerApp] 403 GET /api/kernels?1742395102938 (@127.0.0.1) 0.67ms referer=None
[W 2025-03-19 22:38:22.941 ServerApp] wrote error: 'Forbidden'
    Traceback (most recent call last):
      File "/home/cbel/Desktop/YIHAN/venv/lib/python3.8/site-packages/tornado/web.py", line 1788, in _execute
        result = method(*self.path_args, **self.path_kwargs)
      File "/home/cbel/Desktop/YIHAN/venv/lib/python3.8/site-packages/tornado/web.py", line 3289, in wrapper
        url = self.get_login_url()
      File "/home/cbel/Desktop/YIHAN/venv/lib/python3.8/site-packages/jupyter_server/base/handlers.py", line 783, in get_login_url
        raise web.HTTPError(403)
    tornado.web.HTTPError: HTTP 403: Forbidden
[W 2025-03-19 22:38:22.942 ServerApp] 403 GET /api/sessions?1742395102939 (@127.0.0.1) 0.89ms referer=None
[W 2025-03-19 22:38:22.942 ServerApp] wrote error: 'Forbidden'
    Traceback (most recent call last):
      File "/home/cbel/Desktop/YIHAN/venv/lib/python3.8/site-packages/tornado/web.py", line 1788, in _execute
        result = method(*self.path_args, **self.path_kwargs)
      File "/home/cbel/Desktop/YIHAN/venv/lib/python3.8/site-packages/tornado/web.py", line 3289, in wrapper
        url = self.get_login_url()
      File "/home/cbel/Desktop/YIHAN/venv/lib/python3.8/site-packages/jupyter_server/base/handlers.py", line 783, in get_login_url
        raise web.HTTPError(403)
    tornado.web.HTTPError: HTTP 403: Forbidden
[W 2025-03-19 22:38:22.942 ServerApp] 403 GET /api/kernels?1742395102936 (@127.0.0.1) 0.48ms referer=None
[I 2025-03-19 22:38:22.952 ServerApp] 302 GET / (@127.0.0.1) 0.23ms
[I 2025-03-19 22:38:22.953 JupyterNotebookApp] 302 GET /tree? (@127.0.0.1) 0.31ms
[W 2025-03-19 22:38:23.278 ServerApp] wrote error: 'Forbidden'
    Traceback (most recent call last):
      File "/home/cbel/Desktop/YIHAN/venv/lib/python3.8/site-packages/tornado/web.py", line 1788, in _execute
        result = method(*self.path_args, **self.path_kwargs)
      File "/home/cbel/Desktop/YIHAN/venv/lib/python3.8/site-packages/tornado/web.py", line 3289, in wrapper
        url = self.get_login_url()
      File "/home/cbel/Desktop/YIHAN/venv/lib/python3.8/site-packages/jupyter_server/base/handlers.py", line 783, in get_login_url
        raise web.HTTPError(403)
    tornado.web.HTTPError: HTTP 403: Forbidden
[W 2025-03-19 22:38:23.279 ServerApp] 403 GET /api/kernelspecs?1742395103276 (@127.0.0.1) 0.71ms referer=None
[W 2025-03-19 22:38:23.282 ServerApp] wrote error: 'Forbidden'
    Traceback (most recent call last):
      File "/home/cbel/Desktop/YIHAN/venv/lib/python3.8/site-packages/tornado/web.py", line 1788, in _execute
        result = method(*self.path_args, **self.path_kwargs)
      File "/home/cbel/Desktop/YIHAN/venv/lib/python3.8/site-packages/tornado/web.py", line 3289, in wrapper
        url = self.get_login_url()
      File "/home/cbel/Desktop/YIHAN/venv/lib/python3.8/site-packages/jupyter_server/base/handlers.py", line 783, in get_login_url
        raise web.HTTPError(403)
    tornado.web.HTTPError: HTTP 403: Forbidden
[W 2025-03-19 22:38:23.283 ServerApp] 403 GET /api/kernels?1742395103276 (@127.0.0.1) 0.82ms referer=None
[W 2025-03-19 22:38:23.283 ServerApp] wrote error: 'Forbidden'
    Traceback (most recent call last):
      File "/home/cbel/Desktop/YIHAN/venv/lib/python3.8/site-packages/tornado/web.py", line 1788, in _execute
        result = method(*self.path_args, **self.path_kwargs)
      File "/home/cbel/Desktop/YIHAN/venv/lib/python3.8/site-packages/tornado/web.py", line 3289, in wrapper
        url = self.get_login_url()
      File "/home/cbel/Desktop/YIHAN/venv/lib/python3.8/site-packages/jupyter_server/base/handlers.py", line 783, in get_login_url
        raise web.HTTPError(403)
    tornado.web.HTTPError: HTTP 403: Forbidden
[W 2025-03-19 22:38:23.283 ServerApp] 403 GET /api/kernelspecs?1742395103277 (@127.0.0.1) 1.05ms referer=None
[W 2025-03-19 22:38:23.283 ServerApp] wrote error: 'Forbidden'
    Traceback (most recent call last):
      File "/home/cbel/Desktop/YIHAN/venv/lib/python3.8/site-packages/tornado/web.py", line 1788, in _execute
        result = method(*self.path_args, **self.path_kwargs)
      File "/home/cbel/Desktop/YIHAN/venv/lib/python3.8/site-packages/tornado/web.py", line 3289, in wrapper
        url = self.get_login_url()
      File "/home/cbel/Desktop/YIHAN/venv/lib/python3.8/site-packages/jupyter_server/base/handlers.py", line 783, in get_login_url
        raise web.HTTPError(403)
    tornado.web.HTTPError: HTTP 403: Forbidden
[W 2025-03-19 22:38:23.284 ServerApp] 403 GET /api/kernels?1742395103277 (@127.0.0.1) 1.34ms referer=None
[W 2025-03-19 22:38:23.285 ServerApp] wrote error: 'Forbidden'
    Traceback (most recent call last):
      File "/home/cbel/Desktop/YIHAN/venv/lib/python3.8/site-packages/tornado/web.py", line 1788, in _execute
        result = method(*self.path_args, **self.path_kwargs)
      File "/home/cbel/Desktop/YIHAN/venv/lib/python3.8/site-packages/tornado/web.py", line 3289, in wrapper
        url = self.get_login_url()
      File "/home/cbel/Desktop/YIHAN/venv/lib/python3.8/site-packages/jupyter_server/base/handlers.py", line 783, in get_login_url
        raise web.HTTPError(403)
    tornado.web.HTTPError: HTTP 403: Forbidden
[W 2025-03-19 22:38:23.285 ServerApp] 403 GET /api/kernels?1742395103278 (@127.0.0.1) 1.12ms referer=None
[W 2025-03-19 22:38:23.285 ServerApp] wrote error: 'Forbidden'
    Traceback (most recent call last):
      File "/home/cbel/Desktop/YIHAN/venv/lib/python3.8/site-packages/tornado/web.py", line 1788, in _execute
        result = method(*self.path_args, **self.path_kwargs)
      File "/home/cbel/Desktop/YIHAN/venv/lib/python3.8/site-packages/tornado/web.py", line 3289, in wrapper
        url = self.get_login_url()
      File "/home/cbel/Desktop/YIHAN/venv/lib/python3.8/site-packages/jupyter_server/base/handlers.py", line 783, in get_login_url
        raise web.HTTPError(403)
    tornado.web.HTTPError: HTTP 403: Forbidden
[W 2025-03-19 22:38:23.285 ServerApp] 403 GET /api/sessions?1742395103279 (@127.0.0.1) 1.35ms referer=None
[W 2025-03-19 22:38:23.285 ServerApp] wrote error: 'Forbidden'
    Traceback (most recent call last):
      File "/home/cbel/Desktop/YIHAN/venv/lib/python3.8/site-packages/tornado/web.py", line 1788, in _execute
        result = method(*self.path_args, **self.path_kwargs)
      File "/home/cbel/Desktop/YIHAN/venv/lib/python3.8/site-packages/tornado/web.py", line 3289, in wrapper
        url = self.get_login_url()
      File "/home/cbel/Desktop/YIHAN/venv/lib/python3.8/site-packages/jupyter_server/base/handlers.py", line 783, in get_login_url
        raise web.HTTPError(403)
    tornado.web.HTTPError: HTTP 403: Forbidden
[W 2025-03-19 22:38:23.286 ServerApp] 403 GET /api/kernels?1742395103279 (@127.0.0.1) 1.60ms referer=None
[W 2025-03-19 22:38:23.286 ServerApp] wrote error: 'Forbidden'
    Traceback (most recent call last):
      File "/home/cbel/Desktop/YIHAN/venv/lib/python3.8/site-packages/tornado/web.py", line 1788, in _execute
        result = method(*self.path_args, **self.path_kwargs)
      File "/home/cbel/Desktop/YIHAN/venv/lib/python3.8/site-packages/tornado/web.py", line 3289, in wrapper
        url = self.get_login_url()
      File "/home/cbel/Desktop/YIHAN/venv/lib/python3.8/site-packages/jupyter_server/base/handlers.py", line 783, in get_login_url
        raise web.HTTPError(403)
    tornado.web.HTTPError: HTTP 403: Forbidden
[W 2025-03-19 22:38:23.286 ServerApp] 403 GET /api/sessions?1742395103280 (@127.0.0.1) 1.98ms referer=None
[W 2025-03-19 22:38:23.286 ServerApp] wrote error: 'Forbidden'
    Traceback (most recent call last):
      File "/home/cbel/Desktop/YIHAN/venv/lib/python3.8/site-packages/tornado/web.py", line 1788, in _execute
        result = method(*self.path_args, **self.path_kwargs)
      File "/home/cbel/Desktop/YIHAN/venv/lib/python3.8/site-packages/tornado/web.py", line 3289, in wrapper
        url = self.get_login_url()
      File "/home/cbel/Desktop/YIHAN/venv/lib/python3.8/site-packages/jupyter_server/base/handlers.py", line 783, in get_login_url
        raise web.HTTPError(403)
    tornado.web.HTTPError: HTTP 403: Forbidden
[W 2025-03-19 22:38:23.286 ServerApp] 403 GET /api/kernelspecs?1742395103281 (@127.0.0.1) 2.07ms referer=None
[W 2025-03-19 22:38:23.288 ServerApp] wrote error: 'Forbidden'
    Traceback (most recent call last):
      File "/home/cbel/Desktop/YIHAN/venv/lib/python3.8/site-packages/tornado/web.py", line 1788, in _execute
        result = method(*self.path_args, **self.path_kwargs)
      File "/home/cbel/Desktop/YIHAN/venv/lib/python3.8/site-packages/tornado/web.py", line 3289, in wrapper
        url = self.get_login_url()
      File "/home/cbel/Desktop/YIHAN/venv/lib/python3.8/site-packages/jupyter_server/base/handlers.py", line 783, in get_login_url
        raise web.HTTPError(403)
    tornado.web.HTTPError: HTTP 403: Forbidden
[W 2025-03-19 22:38:23.289 ServerApp] 403 GET /api/kernelspecs?1742395103285 (@127.0.0.1) 0.49ms referer=None
[I 2025-03-19 22:38:23.289 ServerApp] 302 GET / (@127.0.0.1) 0.22ms
[I 2025-03-19 22:38:23.290 JupyterNotebookApp] 302 GET /tree? (@127.0.0.1) 0.33ms
[W 2025-03-19 22:38:23.631 ServerApp] wrote error: 'Forbidden'
    Traceback (most recent call last):
      File "/home/cbel/Desktop/YIHAN/venv/lib/python3.8/site-packages/tornado/web.py", line 1788, in _execute
        result = method(*self.path_args, **self.path_kwargs)
      File "/home/cbel/Desktop/YIHAN/venv/lib/python3.8/site-packages/tornado/web.py", line 3289, in wrapper
        url = self.get_login_url()
      File "/home/cbel/Desktop/YIHAN/venv/lib/python3.8/site-packages/jupyter_server/base/handlers.py", line 783, in get_login_url
        raise web.HTTPError(403)
    tornado.web.HTTPError: HTTP 403: Forbidden
[W 2025-03-19 22:38:23.632 ServerApp] 403 GET /api/kernelspecs?1742395103630 (@127.0.0.1) 0.71ms referer=None
[W 2025-03-19 22:38:23.637 ServerApp] wrote error: 'Forbidden'
    Traceback (most recent call last):
      File "/home/cbel/Desktop/YIHAN/venv/lib/python3.8/site-packages/tornado/web.py", line 1788, in _execute
        result = method(*self.path_args, **self.path_kwargs)
      File "/home/cbel/Desktop/YIHAN/venv/lib/python3.8/site-packages/tornado/web.py", line 3289, in wrapper
        url = self.get_login_url()
      File "/home/cbel/Desktop/YIHAN/venv/lib/python3.8/site-packages/jupyter_server/base/handlers.py", line 783, in get_login_url
        raise web.HTTPError(403)
    tornado.web.HTTPError: HTTP 403: Forbidden
[W 2025-03-19 22:38:23.637 ServerApp] 403 GET /api/kernels?1742395103630 (@127.0.0.1) 0.67ms referer=None
[W 2025-03-19 22:38:23.638 ServerApp] wrote error: 'Forbidden'
    Traceback (most recent call last):
      File "/home/cbel/Desktop/YIHAN/venv/lib/python3.8/site-packages/tornado/web.py", line 1788, in _execute
        result = method(*self.path_args, **self.path_kwargs)
      File "/home/cbel/Desktop/YIHAN/venv/lib/python3.8/site-packages/tornado/web.py", line 3289, in wrapper
        url = self.get_login_url()
      File "/home/cbel/Desktop/YIHAN/venv/lib/python3.8/site-packages/jupyter_server/base/handlers.py", line 783, in get_login_url
        raise web.HTTPError(403)
    tornado.web.HTTPError: HTTP 403: Forbidden
[W 2025-03-19 22:38:23.638 ServerApp] 403 GET /api/kernels?1742395103634 (@127.0.0.1) 0.67ms referer=None
[W 2025-03-19 22:38:23.639 ServerApp] wrote error: 'Forbidden'
    Traceback (most recent call last):
      File "/home/cbel/Desktop/YIHAN/venv/lib/python3.8/site-packages/tornado/web.py", line 1788, in _execute
        result = method(*self.path_args, **self.path_kwargs)
      File "/home/cbel/Desktop/YIHAN/venv/lib/python3.8/site-packages/tornado/web.py", line 3289, in wrapper
        url = self.get_login_url()
      File "/home/cbel/Desktop/YIHAN/venv/lib/python3.8/site-packages/jupyter_server/base/handlers.py", line 783, in get_login_url
        raise web.HTTPError(403)
    tornado.web.HTTPError: HTTP 403: Forbidden
[W 2025-03-19 22:38:23.639 ServerApp] 403 GET /api/sessions?1742395103635 (@127.0.0.1) 0.58ms referer=None
[W 2025-03-19 22:38:23.639 ServerApp] wrote error: 'Forbidden'
    Traceback (most recent call last):
      File "/home/cbel/Desktop/YIHAN/venv/lib/python3.8/site-packages/tornado/web.py", line 1788, in _execute
        result = method(*self.path_args, **self.path_kwargs)
      File "/home/cbel/Desktop/YIHAN/venv/lib/python3.8/site-packages/tornado/web.py", line 3289, in wrapper
        url = self.get_login_url()
      File "/home/cbel/Desktop/YIHAN/venv/lib/python3.8/site-packages/jupyter_server/base/handlers.py", line 783, in get_login_url
        raise web.HTTPError(403)
    tornado.web.HTTPError: HTTP 403: Forbidden
[W 2025-03-19 22:38:23.640 ServerApp] 403 GET /api/kernelspecs?1742395103637 (@127.0.0.1) 0.47ms referer=None
[I 2025-03-19 22:38:25.836 ServerApp] User f33f9f7da540492fa00e9037ce7ae4d3 logged in.
[I 2025-03-19 22:38:25.836 ServerApp] 302 POST /login? (f33f9f7da540492fa00e9037ce7ae4d3@127.0.0.1) 0.62ms
[I 2025-03-19 22:38:25.864 ServerApp] Connecting to kernel c2f5cbbe-5426-4551-b160-3a95988a0bb2.
[I 2025-03-19 22:38:25.974 ServerApp] 302 GET / (@127.0.0.1) 0.25ms
[I 2025-03-19 22:38:25.978 JupyterNotebookApp] 302 GET /tree? (@127.0.0.1) 0.33ms
[I 2025-03-19 22:38:29.659 ServerApp] User 1f446762c18f469887b96f23bb30098e logged in.
[I 2025-03-19 22:38:29.659 ServerApp] 302 POST /login? (1f446762c18f469887b96f23bb30098e@127.0.0.1) 1.02ms
2025-03-19 22:39:42.055261: I tensorflow/stream_executor/cuda/cuda_gpu_executor.cc:939] successful NUMA node read from SysFS had negative value (-1), but there must be at least one NUMA node, so returning NUMA node zero
2025-03-19 22:39:42.095475: I tensorflow/stream_executor/cuda/cuda_gpu_executor.cc:939] successful NUMA node read from SysFS had negative value (-1), but there must be at least one NUMA node, so returning NUMA node zero
2025-03-19 22:39:42.097294: I tensorflow/stream_executor/cuda/cuda_gpu_executor.cc:939] successful NUMA node read from SysFS had negative value (-1), but there must be at least one NUMA node, so returning NUMA node zero
2025-03-19 22:39:42.115236: I tensorflow/core/platform/cpu_feature_guard.cc:151] This TensorFlow binary is optimized with oneAPI Deep Neural Network Library (oneDNN) to use the following CPU instructions in performance-critical operations:  AVX2 FMA
To enable them in other operations, rebuild TensorFlow with the appropriate compiler flags.
2025-03-19 22:39:42.116139: I tensorflow/stream_executor/cuda/cuda_gpu_executor.cc:939] successful NUMA node read from SysFS had negative value (-1), but there must be at least one NUMA node, so returning NUMA node zero
2025-03-19 22:39:42.116680: I tensorflow/stream_executor/cuda/cuda_gpu_executor.cc:939] successful NUMA node read from SysFS had negative value (-1), but there must be at least one NUMA node, so returning NUMA node zero
2025-03-19 22:39:42.117155: I tensorflow/stream_executor/cuda/cuda_gpu_executor.cc:939] successful NUMA node read from SysFS had negative value (-1), but there must be at least one NUMA node, so returning NUMA node zero
2025-03-19 22:39:42.658724: I tensorflow/stream_executor/cuda/cuda_gpu_executor.cc:939] successful NUMA node read from SysFS had negative value (-1), but there must be at least one NUMA node, so returning NUMA node zero
2025-03-19 22:39:42.659229: I tensorflow/stream_executor/cuda/cuda_gpu_executor.cc:939] successful NUMA node read from SysFS had negative value (-1), but there must be at least one NUMA node, so returning NUMA node zero
2025-03-19 22:39:42.659679: I tensorflow/stream_executor/cuda/cuda_gpu_executor.cc:939] successful NUMA node read from SysFS had negative value (-1), but there must be at least one NUMA node, so returning NUMA node zero
2025-03-19 22:39:42.660107: I tensorflow/core/common_runtime/gpu/gpu_process_state.cc:214] Using CUDA malloc Async allocator for GPU: 0
2025-03-19 22:39:42.660712: I tensorflow/core/common_runtime/gpu/gpu_device.cc:1525] Created device /job:localhost/replica:0/task:0/device:GPU:0 with 18432 MB memory:  -> device: 0, name: NVIDIA GeForce RTX 3090, pci bus id: 0000:01:00.0, compute capability: 8.6
[I 2025-03-19 22:43:37.442 ServerApp] AsyncIOLoopKernelRestarter: restarting kernel (1/5), keep random ports
[W 2025-03-19 22:43:37.444 ServerApp] kernel c2f5cbbe-5426-4551-b160-3a95988a0bb2 restarted
[I 2025-03-19 22:43:37.470 ServerApp] Starting buffering for c2f5cbbe-5426-4551-b160-3a95988a0bb2:edc04cfa-c747-46fa-b8f5-637eb1b024d4
[I 2025-03-19 22:43:37.479 ServerApp] Connecting to kernel c2f5cbbe-5426-4551-b160-3a95988a0bb2.
[I 2025-03-19 22:43:37.479 ServerApp] Restoring connection for c2f5cbbe-5426-4551-b160-3a95988a0bb2:edc04cfa-c747-46fa-b8f5-637eb1b024d4
[I 2025-03-19 22:44:11.136 ServerApp] Kernel restarted: c2f5cbbe-5426-4551-b160-3a95988a0bb2
[I 2025-03-19 22:44:11.138 ServerApp] Starting buffering for c2f5cbbe-5426-4551-b160-3a95988a0bb2:edc04cfa-c747-46fa-b8f5-637eb1b024d4
[I 2025-03-19 22:44:11.142 ServerApp] Connecting to kernel c2f5cbbe-5426-4551-b160-3a95988a0bb2.
[I 2025-03-19 22:44:11.142 ServerApp] Restoring connection for c2f5cbbe-5426-4551-b160-3a95988a0bb2:edc04cfa-c747-46fa-b8f5-637eb1b024d4
2025-03-19 22:44:23.086372: I tensorflow/stream_executor/cuda/cuda_gpu_executor.cc:939] successful NUMA node read from SysFS had negative value (-1), but there must be at least one NUMA node, so returning NUMA node zero
2025-03-19 22:44:23.135161: I tensorflow/stream_executor/cuda/cuda_gpu_executor.cc:939] successful NUMA node read from SysFS had negative value (-1), but there must be at least one NUMA node, so returning NUMA node zero
2025-03-19 22:44:23.137026: I tensorflow/stream_executor/cuda/cuda_gpu_executor.cc:939] successful NUMA node read from SysFS had negative value (-1), but there must be at least one NUMA node, so returning NUMA node zero
2025-03-19 22:44:23.152050: I tensorflow/core/platform/cpu_feature_guard.cc:151] This TensorFlow binary is optimized with oneAPI Deep Neural Network Library (oneDNN) to use the following CPU instructions in performance-critical operations:  AVX2 FMA
To enable them in other operations, rebuild TensorFlow with the appropriate compiler flags.
2025-03-19 22:44:23.152944: I tensorflow/stream_executor/cuda/cuda_gpu_executor.cc:939] successful NUMA node read from SysFS had negative value (-1), but there must be at least one NUMA node, so returning NUMA node zero
2025-03-19 22:44:23.153450: I tensorflow/stream_executor/cuda/cuda_gpu_executor.cc:939] successful NUMA node read from SysFS had negative value (-1), but there must be at least one NUMA node, so returning NUMA node zero
2025-03-19 22:44:23.153910: I tensorflow/stream_executor/cuda/cuda_gpu_executor.cc:939] successful NUMA node read from SysFS had negative value (-1), but there must be at least one NUMA node, so returning NUMA node zero
2025-03-19 22:44:23.713998: I tensorflow/stream_executor/cuda/cuda_gpu_executor.cc:939] successful NUMA node read from SysFS had negative value (-1), but there must be at least one NUMA node, so returning NUMA node zero
2025-03-19 22:44:23.714506: I tensorflow/stream_executor/cuda/cuda_gpu_executor.cc:939] successful NUMA node read from SysFS had negative value (-1), but there must be at least one NUMA node, so returning NUMA node zero
2025-03-19 22:44:23.714953: I tensorflow/stream_executor/cuda/cuda_gpu_executor.cc:939] successful NUMA node read from SysFS had negative value (-1), but there must be at least one NUMA node, so returning NUMA node zero
2025-03-19 22:44:23.715378: I tensorflow/core/common_runtime/gpu/gpu_process_state.cc:214] Using CUDA malloc Async allocator for GPU: 0
2025-03-19 22:44:23.715980: I tensorflow/core/common_runtime/gpu/gpu_device.cc:1525] Created device /job:localhost/replica:0/task:0/device:GPU:0 with 18432 MB memory:  -> device: 0, name: NVIDIA GeForce RTX 3090, pci bus id: 0000:01:00.0, compute capability: 8.6
[I 2025-03-19 22:47:41.130 ServerApp] AsyncIOLoopKernelRestarter: restarting kernel (1/5), keep random ports
[W 2025-03-19 22:47:41.133 ServerApp] kernel c2f5cbbe-5426-4551-b160-3a95988a0bb2 restarted
[I 2025-03-19 22:47:41.166 ServerApp] Starting buffering for c2f5cbbe-5426-4551-b160-3a95988a0bb2:edc04cfa-c747-46fa-b8f5-637eb1b024d4
[I 2025-03-19 22:47:41.194 ServerApp] Connecting to kernel c2f5cbbe-5426-4551-b160-3a95988a0bb2.
[I 2025-03-19 22:47:41.194 ServerApp] Restoring connection for c2f5cbbe-5426-4551-b160-3a95988a0bb2:edc04cfa-c747-46fa-b8f5-637eb1b024d4
2025-03-19 22:49:48.621585: I tensorflow/stream_executor/cuda/cuda_gpu_executor.cc:939] successful NUMA node read from SysFS had negative value (-1), but there must be at least one NUMA node, so returning NUMA node zero
2025-03-19 22:49:48.657928: I tensorflow/stream_executor/cuda/cuda_gpu_executor.cc:939] successful NUMA node read from SysFS had negative value (-1), but there must be at least one NUMA node, so returning NUMA node zero
2025-03-19 22:49:48.659038: I tensorflow/stream_executor/cuda/cuda_gpu_executor.cc:939] successful NUMA node read from SysFS had negative value (-1), but there must be at least one NUMA node, so returning NUMA node zero
2025-03-19 22:49:48.698092: I tensorflow/core/platform/cpu_feature_guard.cc:151] This TensorFlow binary is optimized with oneAPI Deep Neural Network Library (oneDNN) to use the following CPU instructions in performance-critical operations:  AVX2 FMA
To enable them in other operations, rebuild TensorFlow with the appropriate compiler flags.
2025-03-19 22:49:48.699747: I tensorflow/stream_executor/cuda/cuda_gpu_executor.cc:939] successful NUMA node read from SysFS had negative value (-1), but there must be at least one NUMA node, so returning NUMA node zero
2025-03-19 22:49:48.701325: I tensorflow/stream_executor/cuda/cuda_gpu_executor.cc:939] successful NUMA node read from SysFS had negative value (-1), but there must be at least one NUMA node, so returning NUMA node zero
2025-03-19 22:49:48.702964: I tensorflow/stream_executor/cuda/cuda_gpu_executor.cc:939] successful NUMA node read from SysFS had negative value (-1), but there must be at least one NUMA node, so returning NUMA node zero
2025-03-19 22:49:49.269804: I tensorflow/stream_executor/cuda/cuda_gpu_executor.cc:939] successful NUMA node read from SysFS had negative value (-1), but there must be at least one NUMA node, so returning NUMA node zero
2025-03-19 22:49:49.270349: I tensorflow/stream_executor/cuda/cuda_gpu_executor.cc:939] successful NUMA node read from SysFS had negative value (-1), but there must be at least one NUMA node, so returning NUMA node zero
2025-03-19 22:49:49.270795: I tensorflow/stream_executor/cuda/cuda_gpu_executor.cc:939] successful NUMA node read from SysFS had negative value (-1), but there must be at least one NUMA node, so returning NUMA node zero
2025-03-19 22:49:49.271219: I tensorflow/core/common_runtime/gpu/gpu_process_state.cc:214] Using CUDA malloc Async allocator for GPU: 0
2025-03-19 22:49:49.271815: I tensorflow/core/common_runtime/gpu/gpu_device.cc:1525] Created device /job:localhost/replica:0/task:0/device:GPU:0 with 18432 MB memory:  -> device: 0, name: NVIDIA GeForce RTX 3090, pci bus id: 0000:01:00.0, compute capability: 8.6
2025-03-19 22:52:43.468309: I tensorflow/stream_executor/cuda/cuda_dnn.cc:366] Loaded cuDNN version 8202
[I 2025-03-19 22:55:49.315 ServerApp] Kernel interrupted: c2f5cbbe-5426-4551-b160-3a95988a0bb2
[I 2025-03-20 05:00:55.139 ServerApp] Starting buffering for c2f5cbbe-5426-4551-b160-3a95988a0bb2:edc04cfa-c747-46fa-b8f5-637eb1b024d4
[I 2025-03-22 13:59:14.733 ServerApp] 302 GET / (@127.0.0.1) 0.30ms
[I 2025-03-22 13:59:14.734 ServerApp] 302 GET / (@127.0.0.1) 0.21ms
[I 2025-03-22 13:59:14.736 JupyterNotebookApp] 302 GET /tree? (@127.0.0.1) 0.36ms
[I 2025-03-22 13:59:14.737 JupyterNotebookApp] 302 GET /tree? (@127.0.0.1) 0.24ms
[W 2025-03-22 13:59:15.305 ServerApp] wrote error: 'Forbidden'
    Traceback (most recent call last):
      File "/home/cbel/Desktop/YIHAN/venv/lib/python3.8/site-packages/tornado/web.py", line 1788, in _execute
        result = method(*self.path_args, **self.path_kwargs)
      File "/home/cbel/Desktop/YIHAN/venv/lib/python3.8/site-packages/tornado/web.py", line 3289, in wrapper
        url = self.get_login_url()
      File "/home/cbel/Desktop/YIHAN/venv/lib/python3.8/site-packages/jupyter_server/base/handlers.py", line 783, in get_login_url
        raise web.HTTPError(403)
    tornado.web.HTTPError: HTTP 403: Forbidden
[W 2025-03-22 13:59:15.305 ServerApp] 403 GET /api/kernelspecs?1742623155290 (@127.0.0.1) 0.80ms referer=None
[W 2025-03-22 13:59:15.310 ServerApp] wrote error: 'Forbidden'
    Traceback (most recent call last):
      File "/home/cbel/Desktop/YIHAN/venv/lib/python3.8/site-packages/tornado/web.py", line 1788, in _execute
        result = method(*self.path_args, **self.path_kwargs)
      File "/home/cbel/Desktop/YIHAN/venv/lib/python3.8/site-packages/tornado/web.py", line 3289, in wrapper
        url = self.get_login_url()
      File "/home/cbel/Desktop/YIHAN/venv/lib/python3.8/site-packages/jupyter_server/base/handlers.py", line 783, in get_login_url
        raise web.HTTPError(403)
    tornado.web.HTTPError: HTTP 403: Forbidden
[W 2025-03-22 13:59:15.310 ServerApp] 403 GET /api/kernels?1742623155292 (@127.0.0.1) 0.59ms referer=None
[W 2025-03-22 13:59:15.311 ServerApp] wrote error: 'Forbidden'
    Traceback (most recent call last):
      File "/home/cbel/Desktop/YIHAN/venv/lib/python3.8/site-packages/tornado/web.py", line 1788, in _execute
        result = method(*self.path_args, **self.path_kwargs)
      File "/home/cbel/Desktop/YIHAN/venv/lib/python3.8/site-packages/tornado/web.py", line 3289, in wrapper
        url = self.get_login_url()
      File "/home/cbel/Desktop/YIHAN/venv/lib/python3.8/site-packages/jupyter_server/base/handlers.py", line 783, in get_login_url
        raise web.HTTPError(403)
    tornado.web.HTTPError: HTTP 403: Forbidden
[W 2025-03-22 13:59:15.311 ServerApp] 403 GET /api/kernels?1742623155304 (@127.0.0.1) 0.44ms referer=None
[W 2025-03-22 13:59:15.311 ServerApp] wrote error: 'Forbidden'
    Traceback (most recent call last):
      File "/home/cbel/Desktop/YIHAN/venv/lib/python3.8/site-packages/tornado/web.py", line 1788, in _execute
        result = method(*self.path_args, **self.path_kwargs)
      File "/home/cbel/Desktop/YIHAN/venv/lib/python3.8/site-packages/tornado/web.py", line 3289, in wrapper
        url = self.get_login_url()
      File "/home/cbel/Desktop/YIHAN/venv/lib/python3.8/site-packages/jupyter_server/base/handlers.py", line 783, in get_login_url
        raise web.HTTPError(403)
    tornado.web.HTTPError: HTTP 403: Forbidden
[W 2025-03-22 13:59:15.312 ServerApp] 403 GET /api/sessions?1742623155305 (@127.0.0.1) 0.51ms referer=None
[W 2025-03-22 13:59:15.313 ServerApp] wrote error: 'Forbidden'
    Traceback (most recent call last):
      File "/home/cbel/Desktop/YIHAN/venv/lib/python3.8/site-packages/tornado/web.py", line 1788, in _execute
        result = method(*self.path_args, **self.path_kwargs)
      File "/home/cbel/Desktop/YIHAN/venv/lib/python3.8/site-packages/tornado/web.py", line 3289, in wrapper
        url = self.get_login_url()
      File "/home/cbel/Desktop/YIHAN/venv/lib/python3.8/site-packages/jupyter_server/base/handlers.py", line 783, in get_login_url
        raise web.HTTPError(403)
    tornado.web.HTTPError: HTTP 403: Forbidden
[W 2025-03-22 13:59:15.313 ServerApp] 403 GET /api/kernelspecs?1742623155310 (@127.0.0.1) 0.47ms referer=None
[I 2025-03-22 13:59:15.320 ServerApp] 302 GET / (@127.0.0.1) 0.28ms
[I 2025-03-22 13:59:15.326 JupyterNotebookApp] 302 GET /tree? (@127.0.0.1) 0.35ms
[W 2025-03-22 13:59:15.477 ServerApp] wrote error: 'Forbidden'
    Traceback (most recent call last):
      File "/home/cbel/Desktop/YIHAN/venv/lib/python3.8/site-packages/tornado/web.py", line 1788, in _execute
        result = method(*self.path_args, **self.path_kwargs)
      File "/home/cbel/Desktop/YIHAN/venv/lib/python3.8/site-packages/tornado/web.py", line 3289, in wrapper
        url = self.get_login_url()
      File "/home/cbel/Desktop/YIHAN/venv/lib/python3.8/site-packages/jupyter_server/base/handlers.py", line 783, in get_login_url
        raise web.HTTPError(403)
    tornado.web.HTTPError: HTTP 403: Forbidden
[W 2025-03-22 13:59:15.477 ServerApp] 403 GET /api/kernelspecs?1742623155474 (@127.0.0.1) 0.66ms referer=None
[W 2025-03-22 13:59:15.484 ServerApp] wrote error: 'Forbidden'
    Traceback (most recent call last):
      File "/home/cbel/Desktop/YIHAN/venv/lib/python3.8/site-packages/tornado/web.py", line 1788, in _execute
        result = method(*self.path_args, **self.path_kwargs)
      File "/home/cbel/Desktop/YIHAN/venv/lib/python3.8/site-packages/tornado/web.py", line 3289, in wrapper
        url = self.get_login_url()
      File "/home/cbel/Desktop/YIHAN/venv/lib/python3.8/site-packages/jupyter_server/base/handlers.py", line 783, in get_login_url
        raise web.HTTPError(403)
    tornado.web.HTTPError: HTTP 403: Forbidden
[W 2025-03-22 13:59:15.485 ServerApp] 403 GET /api/kernels?1742623155475 (@127.0.0.1) 0.65ms referer=None
[W 2025-03-22 13:59:15.485 ServerApp] wrote error: 'Forbidden'
    Traceback (most recent call last):
      File "/home/cbel/Desktop/YIHAN/venv/lib/python3.8/site-packages/tornado/web.py", line 1788, in _execute
        result = method(*self.path_args, **self.path_kwargs)
      File "/home/cbel/Desktop/YIHAN/venv/lib/python3.8/site-packages/tornado/web.py", line 3289, in wrapper
        url = self.get_login_url()
      File "/home/cbel/Desktop/YIHAN/venv/lib/python3.8/site-packages/jupyter_server/base/handlers.py", line 783, in get_login_url
        raise web.HTTPError(403)
    tornado.web.HTTPError: HTTP 403: Forbidden
[W 2025-03-22 13:59:15.485 ServerApp] 403 GET /api/kernelspecs?1742623155475 (@127.0.0.1) 0.63ms referer=None
[W 2025-03-22 13:59:15.485 ServerApp] wrote error: 'Forbidden'
    Traceback (most recent call last):
      File "/home/cbel/Desktop/YIHAN/venv/lib/python3.8/site-packages/tornado/web.py", line 1788, in _execute
        result = method(*self.path_args, **self.path_kwargs)
      File "/home/cbel/Desktop/YIHAN/venv/lib/python3.8/site-packages/tornado/web.py", line 3289, in wrapper
        url = self.get_login_url()
      File "/home/cbel/Desktop/YIHAN/venv/lib/python3.8/site-packages/jupyter_server/base/handlers.py", line 783, in get_login_url
        raise web.HTTPError(403)
    tornado.web.HTTPError: HTTP 403: Forbidden
[W 2025-03-22 13:59:15.486 ServerApp] 403 GET /api/kernels?1742623155475 (@127.0.0.1) 0.88ms referer=None
[W 2025-03-22 13:59:15.487 ServerApp] wrote error: 'Forbidden'
    Traceback (most recent call last):
      File "/home/cbel/Desktop/YIHAN/venv/lib/python3.8/site-packages/tornado/web.py", line 1788, in _execute
        result = method(*self.path_args, **self.path_kwargs)
      File "/home/cbel/Desktop/YIHAN/venv/lib/python3.8/site-packages/tornado/web.py", line 3289, in wrapper
        url = self.get_login_url()
      File "/home/cbel/Desktop/YIHAN/venv/lib/python3.8/site-packages/jupyter_server/base/handlers.py", line 783, in get_login_url
        raise web.HTTPError(403)
    tornado.web.HTTPError: HTTP 403: Forbidden
[W 2025-03-22 13:59:15.487 ServerApp] 403 GET /api/kernels?1742623155477 (@127.0.0.1) 0.82ms referer=None
[W 2025-03-22 13:59:15.487 ServerApp] wrote error: 'Forbidden'
    Traceback (most recent call last):
      File "/home/cbel/Desktop/YIHAN/venv/lib/python3.8/site-packages/tornado/web.py", line 1788, in _execute
        result = method(*self.path_args, **self.path_kwargs)
      File "/home/cbel/Desktop/YIHAN/venv/lib/python3.8/site-packages/tornado/web.py", line 3289, in wrapper
        url = self.get_login_url()
      File "/home/cbel/Desktop/YIHAN/venv/lib/python3.8/site-packages/jupyter_server/base/handlers.py", line 783, in get_login_url
        raise web.HTTPError(403)
    tornado.web.HTTPError: HTTP 403: Forbidden
[W 2025-03-22 13:59:15.487 ServerApp] 403 GET /api/sessions?1742623155478 (@127.0.0.1) 1.07ms referer=None
[W 2025-03-22 13:59:15.487 ServerApp] wrote error: 'Forbidden'
    Traceback (most recent call last):
      File "/home/cbel/Desktop/YIHAN/venv/lib/python3.8/site-packages/tornado/web.py", line 1788, in _execute
        result = method(*self.path_args, **self.path_kwargs)
      File "/home/cbel/Desktop/YIHAN/venv/lib/python3.8/site-packages/tornado/web.py", line 3289, in wrapper
        url = self.get_login_url()
      File "/home/cbel/Desktop/YIHAN/venv/lib/python3.8/site-packages/jupyter_server/base/handlers.py", line 783, in get_login_url
        raise web.HTTPError(403)
    tornado.web.HTTPError: HTTP 403: Forbidden
[W 2025-03-22 13:59:15.488 ServerApp] 403 GET /api/kernels?1742623155478 (@127.0.0.1) 1.32ms referer=None
[W 2025-03-22 13:59:15.488 ServerApp] wrote error: 'Forbidden'
    Traceback (most recent call last):
      File "/home/cbel/Desktop/YIHAN/venv/lib/python3.8/site-packages/tornado/web.py", line 1788, in _execute
        result = method(*self.path_args, **self.path_kwargs)
      File "/home/cbel/Desktop/YIHAN/venv/lib/python3.8/site-packages/tornado/web.py", line 3289, in wrapper
        url = self.get_login_url()
      File "/home/cbel/Desktop/YIHAN/venv/lib/python3.8/site-packages/jupyter_server/base/handlers.py", line 783, in get_login_url
        raise web.HTTPError(403)
    tornado.web.HTTPError: HTTP 403: Forbidden
[W 2025-03-22 13:59:15.488 ServerApp] 403 GET /api/sessions?1742623155478 (@127.0.0.1) 1.58ms referer=None
[W 2025-03-22 13:59:15.489 ServerApp] wrote error: 'Forbidden'
    Traceback (most recent call last):
      File "/home/cbel/Desktop/YIHAN/venv/lib/python3.8/site-packages/tornado/web.py", line 1788, in _execute
        result = method(*self.path_args, **self.path_kwargs)
      File "/home/cbel/Desktop/YIHAN/venv/lib/python3.8/site-packages/tornado/web.py", line 3289, in wrapper
        url = self.get_login_url()
      File "/home/cbel/Desktop/YIHAN/venv/lib/python3.8/site-packages/jupyter_server/base/handlers.py", line 783, in get_login_url
        raise web.HTTPError(403)
    tornado.web.HTTPError: HTTP 403: Forbidden
[W 2025-03-22 13:59:15.489 ServerApp] 403 GET /api/kernelspecs?1742623155484 (@127.0.0.1) 0.45ms referer=None
[W 2025-03-22 13:59:15.490 ServerApp] wrote error: 'Forbidden'
    Traceback (most recent call last):
      File "/home/cbel/Desktop/YIHAN/venv/lib/python3.8/site-packages/tornado/web.py", line 1788, in _execute
        result = method(*self.path_args, **self.path_kwargs)
      File "/home/cbel/Desktop/YIHAN/venv/lib/python3.8/site-packages/tornado/web.py", line 3289, in wrapper
        url = self.get_login_url()
      File "/home/cbel/Desktop/YIHAN/venv/lib/python3.8/site-packages/jupyter_server/base/handlers.py", line 783, in get_login_url
        raise web.HTTPError(403)
    tornado.web.HTTPError: HTTP 403: Forbidden
[W 2025-03-22 13:59:15.491 ServerApp] 403 GET /api/kernelspecs?1742623155487 (@127.0.0.1) 0.48ms referer=None
[I 2025-03-22 13:59:15.491 ServerApp] 302 GET / (@127.0.0.1) 0.20ms
[I 2025-03-22 13:59:15.492 JupyterNotebookApp] 302 GET /tree? (@127.0.0.1) 0.30ms
[W 2025-03-22 13:59:16.019 ServerApp] wrote error: 'Forbidden'
    Traceback (most recent call last):
      File "/home/cbel/Desktop/YIHAN/venv/lib/python3.8/site-packages/tornado/web.py", line 1788, in _execute
        result = method(*self.path_args, **self.path_kwargs)
      File "/home/cbel/Desktop/YIHAN/venv/lib/python3.8/site-packages/tornado/web.py", line 3289, in wrapper
        url = self.get_login_url()
      File "/home/cbel/Desktop/YIHAN/venv/lib/python3.8/site-packages/jupyter_server/base/handlers.py", line 783, in get_login_url
        raise web.HTTPError(403)
    tornado.web.HTTPError: HTTP 403: Forbidden
[W 2025-03-22 13:59:16.020 ServerApp] 403 GET /api/kernelspecs?1742623156018 (@127.0.0.1) 0.75ms referer=None
[W 2025-03-22 13:59:16.021 ServerApp] wrote error: 'Forbidden'
    Traceback (most recent call last):
      File "/home/cbel/Desktop/YIHAN/venv/lib/python3.8/site-packages/tornado/web.py", line 1788, in _execute
        result = method(*self.path_args, **self.path_kwargs)
      File "/home/cbel/Desktop/YIHAN/venv/lib/python3.8/site-packages/tornado/web.py", line 3289, in wrapper
        url = self.get_login_url()
      File "/home/cbel/Desktop/YIHAN/venv/lib/python3.8/site-packages/jupyter_server/base/handlers.py", line 783, in get_login_url
        raise web.HTTPError(403)
    tornado.web.HTTPError: HTTP 403: Forbidden
[W 2025-03-22 13:59:16.021 ServerApp] 403 GET /api/kernels?1742623156018 (@127.0.0.1) 0.50ms referer=None
[W 2025-03-22 13:59:16.022 ServerApp] wrote error: 'Forbidden'
    Traceback (most recent call last):
      File "/home/cbel/Desktop/YIHAN/venv/lib/python3.8/site-packages/tornado/web.py", line 1788, in _execute
        result = method(*self.path_args, **self.path_kwargs)
      File "/home/cbel/Desktop/YIHAN/venv/lib/python3.8/site-packages/tornado/web.py", line 3289, in wrapper
        url = self.get_login_url()
      File "/home/cbel/Desktop/YIHAN/venv/lib/python3.8/site-packages/jupyter_server/base/handlers.py", line 783, in get_login_url
        raise web.HTTPError(403)
    tornado.web.HTTPError: HTTP 403: Forbidden
[W 2025-03-22 13:59:16.022 ServerApp] 403 GET /api/kernels?1742623156019 (@127.0.0.1) 0.62ms referer=None
[W 2025-03-22 13:59:16.022 ServerApp] wrote error: 'Forbidden'
    Traceback (most recent call last):
      File "/home/cbel/Desktop/YIHAN/venv/lib/python3.8/site-packages/tornado/web.py", line 1788, in _execute
        result = method(*self.path_args, **self.path_kwargs)
      File "/home/cbel/Desktop/YIHAN/venv/lib/python3.8/site-packages/tornado/web.py", line 3289, in wrapper
        url = self.get_login_url()
      File "/home/cbel/Desktop/YIHAN/venv/lib/python3.8/site-packages/jupyter_server/base/handlers.py", line 783, in get_login_url
        raise web.HTTPError(403)
    tornado.web.HTTPError: HTTP 403: Forbidden
[W 2025-03-22 13:59:16.022 ServerApp] 403 GET /api/sessions?1742623156020 (@127.0.0.1) 0.89ms referer=None
[W 2025-03-22 13:59:16.023 ServerApp] wrote error: 'Forbidden'
    Traceback (most recent call last):
      File "/home/cbel/Desktop/YIHAN/venv/lib/python3.8/site-packages/tornado/web.py", line 1788, in _execute
        result = method(*self.path_args, **self.path_kwargs)
      File "/home/cbel/Desktop/YIHAN/venv/lib/python3.8/site-packages/tornado/web.py", line 3289, in wrapper
        url = self.get_login_url()
      File "/home/cbel/Desktop/YIHAN/venv/lib/python3.8/site-packages/jupyter_server/base/handlers.py", line 783, in get_login_url
        raise web.HTTPError(403)
    tornado.web.HTTPError: HTTP 403: Forbidden
[W 2025-03-22 13:59:16.023 ServerApp] 403 GET /api/kernelspecs?1742623156021 (@127.0.0.1) 0.48ms referer=None
[I 2025-03-22 13:59:18.212 ServerApp] User 2a6a6ff3edf8403dbc73d9441d0ebab3 logged in.
[I 2025-03-22 13:59:18.213 ServerApp] 302 POST /login? (2a6a6ff3edf8403dbc73d9441d0ebab3@127.0.0.1) 0.92ms
[I 2025-03-22 13:59:18.245 ServerApp] Connecting to kernel c2f5cbbe-5426-4551-b160-3a95988a0bb2.
[I 2025-03-22 13:59:18.355 ServerApp] 302 GET / (@127.0.0.1) 0.28ms
[I 2025-03-22 13:59:18.363 JupyterNotebookApp] 302 GET /tree? (@127.0.0.1) 1.39ms
[I 2025-03-22 13:59:40.335 ServerApp] User fa34a4fbf9f24a4e8f6352b794f19464 logged in.
[I 2025-03-22 13:59:40.337 ServerApp] 302 POST /login? (fa34a4fbf9f24a4e8f6352b794f19464@127.0.0.1) 3.24ms
[I 2025-03-22 14:03:42.640 ServerApp] Starting buffering for c2f5cbbe-5426-4551-b160-3a95988a0bb2:5ced5652-3b5e-4fec-a5f9-38324f91dad5
[I 2025-03-22 14:03:52.748 ServerApp] Connecting to kernel c2f5cbbe-5426-4551-b160-3a95988a0bb2.
[I 2025-03-22 14:08:23.162 ServerApp] AsyncIOLoopKernelRestarter: restarting kernel (1/5), keep random ports
[W 2025-03-22 14:08:23.163 ServerApp] kernel c2f5cbbe-5426-4551-b160-3a95988a0bb2 restarted
[I 2025-03-22 14:08:23.195 ServerApp] Starting buffering for c2f5cbbe-5426-4551-b160-3a95988a0bb2:609d5812-4ad9-4465-87d8-a82fed5ca795
[I 2025-03-22 14:08:23.206 ServerApp] Connecting to kernel c2f5cbbe-5426-4551-b160-3a95988a0bb2.
[I 2025-03-22 14:08:23.207 ServerApp] Restoring connection for c2f5cbbe-5426-4551-b160-3a95988a0bb2:609d5812-4ad9-4465-87d8-a82fed5ca795
[I 2025-03-22 14:08:40.686 ServerApp] Kernel restarted: c2f5cbbe-5426-4551-b160-3a95988a0bb2
[I 2025-03-22 14:08:40.688 ServerApp] Starting buffering for c2f5cbbe-5426-4551-b160-3a95988a0bb2:609d5812-4ad9-4465-87d8-a82fed5ca795
[I 2025-03-22 14:08:40.691 ServerApp] Connecting to kernel c2f5cbbe-5426-4551-b160-3a95988a0bb2.
[I 2025-03-22 14:08:40.691 ServerApp] Restoring connection for c2f5cbbe-5426-4551-b160-3a95988a0bb2:609d5812-4ad9-4465-87d8-a82fed5ca795
[I 2025-03-22 14:14:55.139 ServerApp] Starting buffering for c2f5cbbe-5426-4551-b160-3a95988a0bb2:609d5812-4ad9-4465-87d8-a82fed5ca795
[I 2025-03-22 14:22:31.277 ServerApp] 302 GET / (@127.0.0.1) 0.27ms
[I 2025-03-22 14:22:31.278 ServerApp] 302 GET / (@127.0.0.1) 0.20ms
[I 2025-03-22 14:22:31.281 JupyterNotebookApp] 302 GET /tree? (@127.0.0.1) 0.35ms
[I 2025-03-22 14:22:31.282 JupyterNotebookApp] 302 GET /tree? (@127.0.0.1) 0.37ms
[W 2025-03-22 14:22:31.819 ServerApp] wrote error: 'Forbidden'
    Traceback (most recent call last):
      File "/home/cbel/Desktop/YIHAN/venv/lib/python3.8/site-packages/tornado/web.py", line 1788, in _execute
        result = method(*self.path_args, **self.path_kwargs)
      File "/home/cbel/Desktop/YIHAN/venv/lib/python3.8/site-packages/tornado/web.py", line 3289, in wrapper
        url = self.get_login_url()
      File "/home/cbel/Desktop/YIHAN/venv/lib/python3.8/site-packages/jupyter_server/base/handlers.py", line 783, in get_login_url
        raise web.HTTPError(403)
    tornado.web.HTTPError: HTTP 403: Forbidden
[W 2025-03-22 14:22:31.819 ServerApp] 403 GET /api/kernelspecs?1742624551805 (@127.0.0.1) 0.74ms referer=None
[W 2025-03-22 14:22:31.821 ServerApp] wrote error: 'Forbidden'
    Traceback (most recent call last):
      File "/home/cbel/Desktop/YIHAN/venv/lib/python3.8/site-packages/tornado/web.py", line 1788, in _execute
        result = method(*self.path_args, **self.path_kwargs)
      File "/home/cbel/Desktop/YIHAN/venv/lib/python3.8/site-packages/tornado/web.py", line 3289, in wrapper
        url = self.get_login_url()
      File "/home/cbel/Desktop/YIHAN/venv/lib/python3.8/site-packages/jupyter_server/base/handlers.py", line 783, in get_login_url
        raise web.HTTPError(403)
    tornado.web.HTTPError: HTTP 403: Forbidden
[W 2025-03-22 14:22:31.822 ServerApp] 403 GET /api/kernels?1742624551806 (@127.0.0.1) 0.49ms referer=None
[W 2025-03-22 14:22:31.822 ServerApp] wrote error: 'Forbidden'
    Traceback (most recent call last):
      File "/home/cbel/Desktop/YIHAN/venv/lib/python3.8/site-packages/tornado/web.py", line 1788, in _execute
        result = method(*self.path_args, **self.path_kwargs)
      File "/home/cbel/Desktop/YIHAN/venv/lib/python3.8/site-packages/tornado/web.py", line 3289, in wrapper
        url = self.get_login_url()
      File "/home/cbel/Desktop/YIHAN/venv/lib/python3.8/site-packages/jupyter_server/base/handlers.py", line 783, in get_login_url
        raise web.HTTPError(403)
    tornado.web.HTTPError: HTTP 403: Forbidden
[W 2025-03-22 14:22:31.822 ServerApp] 403 GET /api/kernels?1742624551819 (@127.0.0.1) 0.43ms referer=None
[W 2025-03-22 14:22:31.823 ServerApp] wrote error: 'Forbidden'
    Traceback (most recent call last):
      File "/home/cbel/Desktop/YIHAN/venv/lib/python3.8/site-packages/tornado/web.py", line 1788, in _execute
        result = method(*self.path_args, **self.path_kwargs)
      File "/home/cbel/Desktop/YIHAN/venv/lib/python3.8/site-packages/tornado/web.py", line 3289, in wrapper
        url = self.get_login_url()
      File "/home/cbel/Desktop/YIHAN/venv/lib/python3.8/site-packages/jupyter_server/base/handlers.py", line 783, in get_login_url
        raise web.HTTPError(403)
    tornado.web.HTTPError: HTTP 403: Forbidden
[W 2025-03-22 14:22:31.823 ServerApp] 403 GET /api/sessions?1742624551819 (@127.0.0.1) 0.45ms referer=None
[W 2025-03-22 14:22:31.831 ServerApp] wrote error: 'Forbidden'
    Traceback (most recent call last):
      File "/home/cbel/Desktop/YIHAN/venv/lib/python3.8/site-packages/tornado/web.py", line 1788, in _execute
        result = method(*self.path_args, **self.path_kwargs)
      File "/home/cbel/Desktop/YIHAN/venv/lib/python3.8/site-packages/tornado/web.py", line 3289, in wrapper
        url = self.get_login_url()
      File "/home/cbel/Desktop/YIHAN/venv/lib/python3.8/site-packages/jupyter_server/base/handlers.py", line 783, in get_login_url
        raise web.HTTPError(403)
    tornado.web.HTTPError: HTTP 403: Forbidden
[W 2025-03-22 14:22:31.832 ServerApp] 403 GET /api/kernelspecs?1742624551825 (@127.0.0.1) 0.55ms referer=None
[I 2025-03-22 14:22:31.837 ServerApp] 302 GET / (@127.0.0.1) 0.23ms
[I 2025-03-22 14:22:31.838 JupyterNotebookApp] 302 GET /tree? (@127.0.0.1) 0.29ms
[W 2025-03-22 14:22:32.153 ServerApp] wrote error: 'Forbidden'
    Traceback (most recent call last):
      File "/home/cbel/Desktop/YIHAN/venv/lib/python3.8/site-packages/tornado/web.py", line 1788, in _execute
        result = method(*self.path_args, **self.path_kwargs)
      File "/home/cbel/Desktop/YIHAN/venv/lib/python3.8/site-packages/tornado/web.py", line 3289, in wrapper
        url = self.get_login_url()
      File "/home/cbel/Desktop/YIHAN/venv/lib/python3.8/site-packages/jupyter_server/base/handlers.py", line 783, in get_login_url
        raise web.HTTPError(403)
    tornado.web.HTTPError: HTTP 403: Forbidden
[W 2025-03-22 14:22:32.154 ServerApp] 403 GET /api/kernelspecs?1742624552151 (@127.0.0.1) 0.62ms referer=None
[W 2025-03-22 14:22:32.161 ServerApp] wrote error: 'Forbidden'
    Traceback (most recent call last):
      File "/home/cbel/Desktop/YIHAN/venv/lib/python3.8/site-packages/tornado/web.py", line 1788, in _execute
        result = method(*self.path_args, **self.path_kwargs)
      File "/home/cbel/Desktop/YIHAN/venv/lib/python3.8/site-packages/tornado/web.py", line 3289, in wrapper
        url = self.get_login_url()
      File "/home/cbel/Desktop/YIHAN/venv/lib/python3.8/site-packages/jupyter_server/base/handlers.py", line 783, in get_login_url
        raise web.HTTPError(403)
    tornado.web.HTTPError: HTTP 403: Forbidden
[W 2025-03-22 14:22:32.161 ServerApp] 403 GET /api/kernels?1742624552151 (@127.0.0.1) 0.66ms referer=None
[W 2025-03-22 14:22:32.162 ServerApp] wrote error: 'Forbidden'
    Traceback (most recent call last):
      File "/home/cbel/Desktop/YIHAN/venv/lib/python3.8/site-packages/tornado/web.py", line 1788, in _execute
        result = method(*self.path_args, **self.path_kwargs)
      File "/home/cbel/Desktop/YIHAN/venv/lib/python3.8/site-packages/tornado/web.py", line 3289, in wrapper
        url = self.get_login_url()
      File "/home/cbel/Desktop/YIHAN/venv/lib/python3.8/site-packages/jupyter_server/base/handlers.py", line 783, in get_login_url
        raise web.HTTPError(403)
    tornado.web.HTTPError: HTTP 403: Forbidden
[W 2025-03-22 14:22:32.162 ServerApp] 403 GET /api/kernelspecs?1742624552151 (@127.0.0.1) 0.67ms referer=None
[W 2025-03-22 14:22:32.162 ServerApp] wrote error: 'Forbidden'
    Traceback (most recent call last):
      File "/home/cbel/Desktop/YIHAN/venv/lib/python3.8/site-packages/tornado/web.py", line 1788, in _execute
        result = method(*self.path_args, **self.path_kwargs)
      File "/home/cbel/Desktop/YIHAN/venv/lib/python3.8/site-packages/tornado/web.py", line 3289, in wrapper
        url = self.get_login_url()
      File "/home/cbel/Desktop/YIHAN/venv/lib/python3.8/site-packages/jupyter_server/base/handlers.py", line 783, in get_login_url
        raise web.HTTPError(403)
    tornado.web.HTTPError: HTTP 403: Forbidden
[W 2025-03-22 14:22:32.162 ServerApp] 403 GET /api/kernels?1742624552152 (@127.0.0.1) 0.90ms referer=None
[W 2025-03-22 14:22:32.163 ServerApp] wrote error: 'Forbidden'
    Traceback (most recent call last):
      File "/home/cbel/Desktop/YIHAN/venv/lib/python3.8/site-packages/tornado/web.py", line 1788, in _execute
        result = method(*self.path_args, **self.path_kwargs)
      File "/home/cbel/Desktop/YIHAN/venv/lib/python3.8/site-packages/tornado/web.py", line 3289, in wrapper
        url = self.get_login_url()
      File "/home/cbel/Desktop/YIHAN/venv/lib/python3.8/site-packages/jupyter_server/base/handlers.py", line 783, in get_login_url
        raise web.HTTPError(403)
    tornado.web.HTTPError: HTTP 403: Forbidden
[W 2025-03-22 14:22:32.163 ServerApp] 403 GET /api/kernels?1742624552153 (@127.0.0.1) 0.67ms referer=None
[W 2025-03-22 14:22:32.163 ServerApp] wrote error: 'Forbidden'
    Traceback (most recent call last):
      File "/home/cbel/Desktop/YIHAN/venv/lib/python3.8/site-packages/tornado/web.py", line 1788, in _execute
        result = method(*self.path_args, **self.path_kwargs)
      File "/home/cbel/Desktop/YIHAN/venv/lib/python3.8/site-packages/tornado/web.py", line 3289, in wrapper
        url = self.get_login_url()
      File "/home/cbel/Desktop/YIHAN/venv/lib/python3.8/site-packages/jupyter_server/base/handlers.py", line 783, in get_login_url
        raise web.HTTPError(403)
    tornado.web.HTTPError: HTTP 403: Forbidden
[W 2025-03-22 14:22:32.163 ServerApp] 403 GET /api/sessions?1742624552153 (@127.0.0.1) 0.92ms referer=None
[W 2025-03-22 14:22:32.164 ServerApp] wrote error: 'Forbidden'
    Traceback (most recent call last):
      File "/home/cbel/Desktop/YIHAN/venv/lib/python3.8/site-packages/tornado/web.py", line 1788, in _execute
        result = method(*self.path_args, **self.path_kwargs)
      File "/home/cbel/Desktop/YIHAN/venv/lib/python3.8/site-packages/tornado/web.py", line 3289, in wrapper
        url = self.get_login_url()
      File "/home/cbel/Desktop/YIHAN/venv/lib/python3.8/site-packages/jupyter_server/base/handlers.py", line 783, in get_login_url
        raise web.HTTPError(403)
    tornado.web.HTTPError: HTTP 403: Forbidden
[W 2025-03-22 14:22:32.164 ServerApp] 403 GET /api/kernels?1742624552154 (@127.0.0.1) 0.99ms referer=None
[W 2025-03-22 14:22:32.165 ServerApp] wrote error: 'Forbidden'
    Traceback (most recent call last):
      File "/home/cbel/Desktop/YIHAN/venv/lib/python3.8/site-packages/tornado/web.py", line 1788, in _execute
        result = method(*self.path_args, **self.path_kwargs)
      File "/home/cbel/Desktop/YIHAN/venv/lib/python3.8/site-packages/tornado/web.py", line 3289, in wrapper
        url = self.get_login_url()
      File "/home/cbel/Desktop/YIHAN/venv/lib/python3.8/site-packages/jupyter_server/base/handlers.py", line 783, in get_login_url
        raise web.HTTPError(403)
    tornado.web.HTTPError: HTTP 403: Forbidden
[W 2025-03-22 14:22:32.165 ServerApp] 403 GET /api/sessions?1742624552154 (@127.0.0.1) 1.27ms referer=None
[W 2025-03-22 14:22:32.165 ServerApp] wrote error: 'Forbidden'
    Traceback (most recent call last):
      File "/home/cbel/Desktop/YIHAN/venv/lib/python3.8/site-packages/tornado/web.py", line 1788, in _execute
        result = method(*self.path_args, **self.path_kwargs)
      File "/home/cbel/Desktop/YIHAN/venv/lib/python3.8/site-packages/tornado/web.py", line 3289, in wrapper
        url = self.get_login_url()
      File "/home/cbel/Desktop/YIHAN/venv/lib/python3.8/site-packages/jupyter_server/base/handlers.py", line 783, in get_login_url
        raise web.HTTPError(403)
    tornado.web.HTTPError: HTTP 403: Forbidden
[W 2025-03-22 14:22:32.165 ServerApp] 403 GET /api/kernelspecs?1742624552160 (@127.0.0.1) 1.46ms referer=None
[W 2025-03-22 14:22:32.167 ServerApp] wrote error: 'Forbidden'
    Traceback (most recent call last):
      File "/home/cbel/Desktop/YIHAN/venv/lib/python3.8/site-packages/tornado/web.py", line 1788, in _execute
        result = method(*self.path_args, **self.path_kwargs)
      File "/home/cbel/Desktop/YIHAN/venv/lib/python3.8/site-packages/tornado/web.py", line 3289, in wrapper
        url = self.get_login_url()
      File "/home/cbel/Desktop/YIHAN/venv/lib/python3.8/site-packages/jupyter_server/base/handlers.py", line 783, in get_login_url
        raise web.HTTPError(403)
    tornado.web.HTTPError: HTTP 403: Forbidden
[W 2025-03-22 14:22:32.168 ServerApp] 403 GET /api/kernelspecs?1742624552164 (@127.0.0.1) 0.46ms referer=None
[I 2025-03-22 14:22:32.168 ServerApp] 302 GET / (@127.0.0.1) 0.18ms
[I 2025-03-22 14:22:32.171 JupyterNotebookApp] 302 GET /tree? (@127.0.0.1) 0.29ms
[W 2025-03-22 14:22:32.310 ServerApp] wrote error: 'Forbidden'
    Traceback (most recent call last):
      File "/home/cbel/Desktop/YIHAN/venv/lib/python3.8/site-packages/tornado/web.py", line 1788, in _execute
        result = method(*self.path_args, **self.path_kwargs)
      File "/home/cbel/Desktop/YIHAN/venv/lib/python3.8/site-packages/tornado/web.py", line 3289, in wrapper
        url = self.get_login_url()
      File "/home/cbel/Desktop/YIHAN/venv/lib/python3.8/site-packages/jupyter_server/base/handlers.py", line 783, in get_login_url
        raise web.HTTPError(403)
    tornado.web.HTTPError: HTTP 403: Forbidden
[W 2025-03-22 14:22:32.311 ServerApp] 403 GET /api/kernelspecs?1742624552309 (@127.0.0.1) 0.69ms referer=None
[W 2025-03-22 14:22:32.315 ServerApp] wrote error: 'Forbidden'
    Traceback (most recent call last):
      File "/home/cbel/Desktop/YIHAN/venv/lib/python3.8/site-packages/tornado/web.py", line 1788, in _execute
        result = method(*self.path_args, **self.path_kwargs)
      File "/home/cbel/Desktop/YIHAN/venv/lib/python3.8/site-packages/tornado/web.py", line 3289, in wrapper
        url = self.get_login_url()
      File "/home/cbel/Desktop/YIHAN/venv/lib/python3.8/site-packages/jupyter_server/base/handlers.py", line 783, in get_login_url
        raise web.HTTPError(403)
    tornado.web.HTTPError: HTTP 403: Forbidden
[W 2025-03-22 14:22:32.315 ServerApp] 403 GET /api/kernels?1742624552309 (@127.0.0.1) 0.56ms referer=None
[W 2025-03-22 14:22:32.316 ServerApp] wrote error: 'Forbidden'
    Traceback (most recent call last):
      File "/home/cbel/Desktop/YIHAN/venv/lib/python3.8/site-packages/tornado/web.py", line 1788, in _execute
        result = method(*self.path_args, **self.path_kwargs)
      File "/home/cbel/Desktop/YIHAN/venv/lib/python3.8/site-packages/tornado/web.py", line 3289, in wrapper
        url = self.get_login_url()
      File "/home/cbel/Desktop/YIHAN/venv/lib/python3.8/site-packages/jupyter_server/base/handlers.py", line 783, in get_login_url
        raise web.HTTPError(403)
    tornado.web.HTTPError: HTTP 403: Forbidden
[W 2025-03-22 14:22:32.316 ServerApp] 403 GET /api/kernels?1742624552313 (@127.0.0.1) 0.59ms referer=None
[W 2025-03-22 14:22:32.316 ServerApp] wrote error: 'Forbidden'
    Traceback (most recent call last):
      File "/home/cbel/Desktop/YIHAN/venv/lib/python3.8/site-packages/tornado/web.py", line 1788, in _execute
        result = method(*self.path_args, **self.path_kwargs)
      File "/home/cbel/Desktop/YIHAN/venv/lib/python3.8/site-packages/tornado/web.py", line 3289, in wrapper
        url = self.get_login_url()
      File "/home/cbel/Desktop/YIHAN/venv/lib/python3.8/site-packages/jupyter_server/base/handlers.py", line 783, in get_login_url
        raise web.HTTPError(403)
    tornado.web.HTTPError: HTTP 403: Forbidden
[W 2025-03-22 14:22:32.316 ServerApp] 403 GET /api/sessions?1742624552313 (@127.0.0.1) 0.83ms referer=None
[W 2025-03-22 14:22:32.317 ServerApp] wrote error: 'Forbidden'
    Traceback (most recent call last):
      File "/home/cbel/Desktop/YIHAN/venv/lib/python3.8/site-packages/tornado/web.py", line 1788, in _execute
        result = method(*self.path_args, **self.path_kwargs)
      File "/home/cbel/Desktop/YIHAN/venv/lib/python3.8/site-packages/tornado/web.py", line 3289, in wrapper
        url = self.get_login_url()
      File "/home/cbel/Desktop/YIHAN/venv/lib/python3.8/site-packages/jupyter_server/base/handlers.py", line 783, in get_login_url
        raise web.HTTPError(403)
    tornado.web.HTTPError: HTTP 403: Forbidden
[W 2025-03-22 14:22:32.317 ServerApp] 403 GET /api/kernelspecs?1742624552315 (@127.0.0.1) 0.50ms referer=None
[I 2025-03-22 14:22:34.224 ServerApp] User cee168e68cb643028991f003a94350ad logged in.
[I 2025-03-22 14:22:34.225 ServerApp] 302 POST /login? (cee168e68cb643028991f003a94350ad@127.0.0.1) 0.74ms
[I 2025-03-22 14:22:34.262 ServerApp] Connecting to kernel c2f5cbbe-5426-4551-b160-3a95988a0bb2.
[I 2025-03-22 14:22:34.377 ServerApp] 302 GET / (@127.0.0.1) 0.63ms
[I 2025-03-22 14:22:34.381 JupyterNotebookApp] 302 GET /tree? (@127.0.0.1) 0.68ms
[I 2025-03-22 14:22:58.502 ServerApp] Starting buffering for c2f5cbbe-5426-4551-b160-3a95988a0bb2:f0ba794b-5f0f-4170-9f63-362d5b5e5d6f
[I 2025-03-22 14:22:59.998 ServerApp] User 1e0756219c7442af8a6539d78f5800b3 logged in.
[I 2025-03-22 14:22:59.999 ServerApp] 302 POST /login? (1e0756219c7442af8a6539d78f5800b3@127.0.0.1) 2.90ms
[I 2025-03-22 14:23:03.328 ServerApp] Connecting to kernel c2f5cbbe-5426-4551-b160-3a95988a0bb2.
[I 2025-03-22 14:28:12.298 ServerApp] Kernel interrupted: c2f5cbbe-5426-4551-b160-3a95988a0bb2
[I 2025-03-22 14:28:30.441 ServerApp] Kernel restarted: c2f5cbbe-5426-4551-b160-3a95988a0bb2
[I 2025-03-22 14:28:30.445 ServerApp] Starting buffering for c2f5cbbe-5426-4551-b160-3a95988a0bb2:db9de340-a1dd-4c56-9d88-7738e308f415
[I 2025-03-22 14:28:30.449 ServerApp] Connecting to kernel c2f5cbbe-5426-4551-b160-3a95988a0bb2.
[I 2025-03-22 14:28:30.449 ServerApp] Restoring connection for c2f5cbbe-5426-4551-b160-3a95988a0bb2:db9de340-a1dd-4c56-9d88-7738e308f415
[I 2025-03-22 14:43:00.432 ServerApp] AsyncIOLoopKernelRestarter: restarting kernel (1/5), keep random ports
[W 2025-03-22 14:43:00.434 ServerApp] kernel c2f5cbbe-5426-4551-b160-3a95988a0bb2 restarted
[I 2025-03-22 14:43:00.459 ServerApp] Starting buffering for c2f5cbbe-5426-4551-b160-3a95988a0bb2:db9de340-a1dd-4c56-9d88-7738e308f415
[I 2025-03-22 14:43:00.470 ServerApp] Connecting to kernel c2f5cbbe-5426-4551-b160-3a95988a0bb2.
[I 2025-03-22 14:43:00.470 ServerApp] Restoring connection for c2f5cbbe-5426-4551-b160-3a95988a0bb2:db9de340-a1dd-4c56-9d88-7738e308f415
[I 2025-03-22 14:43:12.179 ServerApp] Kernel restarted: c2f5cbbe-5426-4551-b160-3a95988a0bb2
[I 2025-03-22 14:43:12.181 ServerApp] Starting buffering for c2f5cbbe-5426-4551-b160-3a95988a0bb2:db9de340-a1dd-4c56-9d88-7738e308f415
[I 2025-03-22 14:43:12.184 ServerApp] Connecting to kernel c2f5cbbe-5426-4551-b160-3a95988a0bb2.
[I 2025-03-22 14:43:12.184 ServerApp] Restoring connection for c2f5cbbe-5426-4551-b160-3a95988a0bb2:db9de340-a1dd-4c56-9d88-7738e308f415
[I 2025-03-22 14:46:00.822 ServerApp] Kernel restarted: c2f5cbbe-5426-4551-b160-3a95988a0bb2
[I 2025-03-22 14:46:00.825 ServerApp] Starting buffering for c2f5cbbe-5426-4551-b160-3a95988a0bb2:db9de340-a1dd-4c56-9d88-7738e308f415
[I 2025-03-22 14:46:00.830 ServerApp] Connecting to kernel c2f5cbbe-5426-4551-b160-3a95988a0bb2.
[I 2025-03-22 14:46:00.830 ServerApp] Restoring connection for c2f5cbbe-5426-4551-b160-3a95988a0bb2:db9de340-a1dd-4c56-9d88-7738e308f415
[I 2025-03-22 15:31:16.129 ServerApp] Starting buffering for c2f5cbbe-5426-4551-b160-3a95988a0bb2:db9de340-a1dd-4c56-9d88-7738e308f415
[I 2025-03-22 15:32:03.161 ServerApp] 302 GET / (@127.0.0.1) 0.41ms
[I 2025-03-22 15:32:03.161 ServerApp] 302 GET / (@127.0.0.1) 0.31ms
[I 2025-03-22 15:32:03.166 JupyterNotebookApp] 302 GET /tree? (@127.0.0.1) 0.37ms
[I 2025-03-22 15:32:03.167 JupyterNotebookApp] 302 GET /tree? (@127.0.0.1) 0.39ms
[W 2025-03-22 15:32:04.247 ServerApp] wrote error: 'Forbidden'
    Traceback (most recent call last):
      File "/home/cbel/Desktop/YIHAN/venv/lib/python3.8/site-packages/tornado/web.py", line 1788, in _execute
        result = method(*self.path_args, **self.path_kwargs)
      File "/home/cbel/Desktop/YIHAN/venv/lib/python3.8/site-packages/tornado/web.py", line 3289, in wrapper
        url = self.get_login_url()
      File "/home/cbel/Desktop/YIHAN/venv/lib/python3.8/site-packages/jupyter_server/base/handlers.py", line 783, in get_login_url
        raise web.HTTPError(403)
    tornado.web.HTTPError: HTTP 403: Forbidden
[W 2025-03-22 15:32:04.247 ServerApp] 403 GET /api/kernelspecs?1742628724243 (@127.0.0.1) 1.08ms referer=None
[W 2025-03-22 15:32:04.250 ServerApp] wrote error: 'Forbidden'
    Traceback (most recent call last):
      File "/home/cbel/Desktop/YIHAN/venv/lib/python3.8/site-packages/tornado/web.py", line 1788, in _execute
        result = method(*self.path_args, **self.path_kwargs)
      File "/home/cbel/Desktop/YIHAN/venv/lib/python3.8/site-packages/tornado/web.py", line 3289, in wrapper
        url = self.get_login_url()
      File "/home/cbel/Desktop/YIHAN/venv/lib/python3.8/site-packages/jupyter_server/base/handlers.py", line 783, in get_login_url
        raise web.HTTPError(403)
    tornado.web.HTTPError: HTTP 403: Forbidden
[W 2025-03-22 15:32:04.250 ServerApp] 403 GET /api/kernels?1742628724245 (@127.0.0.1) 0.78ms referer=None
[W 2025-03-22 15:32:04.251 ServerApp] wrote error: 'Forbidden'
    Traceback (most recent call last):
      File "/home/cbel/Desktop/YIHAN/venv/lib/python3.8/site-packages/tornado/web.py", line 1788, in _execute
        result = method(*self.path_args, **self.path_kwargs)
      File "/home/cbel/Desktop/YIHAN/venv/lib/python3.8/site-packages/tornado/web.py", line 3289, in wrapper
        url = self.get_login_url()
      File "/home/cbel/Desktop/YIHAN/venv/lib/python3.8/site-packages/jupyter_server/base/handlers.py", line 783, in get_login_url
        raise web.HTTPError(403)
    tornado.web.HTTPError: HTTP 403: Forbidden
[W 2025-03-22 15:32:04.251 ServerApp] 403 GET /api/kernels?1742628724247 (@127.0.0.1) 0.66ms referer=None
[W 2025-03-22 15:32:04.252 ServerApp] wrote error: 'Forbidden'
    Traceback (most recent call last):
      File "/home/cbel/Desktop/YIHAN/venv/lib/python3.8/site-packages/tornado/web.py", line 1788, in _execute
        result = method(*self.path_args, **self.path_kwargs)
      File "/home/cbel/Desktop/YIHAN/venv/lib/python3.8/site-packages/tornado/web.py", line 3289, in wrapper
        url = self.get_login_url()
      File "/home/cbel/Desktop/YIHAN/venv/lib/python3.8/site-packages/jupyter_server/base/handlers.py", line 783, in get_login_url
        raise web.HTTPError(403)
    tornado.web.HTTPError: HTTP 403: Forbidden
[W 2025-03-22 15:32:04.252 ServerApp] 403 GET /api/sessions?1742628724248 (@127.0.0.1) 0.72ms referer=None
[W 2025-03-22 15:32:04.254 ServerApp] wrote error: 'Forbidden'
    Traceback (most recent call last):
      File "/home/cbel/Desktop/YIHAN/venv/lib/python3.8/site-packages/tornado/web.py", line 1788, in _execute
        result = method(*self.path_args, **self.path_kwargs)
      File "/home/cbel/Desktop/YIHAN/venv/lib/python3.8/site-packages/tornado/web.py", line 3289, in wrapper
        url = self.get_login_url()
      File "/home/cbel/Desktop/YIHAN/venv/lib/python3.8/site-packages/jupyter_server/base/handlers.py", line 783, in get_login_url
        raise web.HTTPError(403)
    tornado.web.HTTPError: HTTP 403: Forbidden
[W 2025-03-22 15:32:04.255 ServerApp] 403 GET /api/kernelspecs?1742628724251 (@127.0.0.1) 0.72ms referer=None
[I 2025-03-22 15:32:04.260 ServerApp] 302 GET / (@127.0.0.1) 0.22ms
[I 2025-03-22 15:32:04.261 JupyterNotebookApp] 302 GET /tree? (@127.0.0.1) 0.32ms
[W 2025-03-22 15:32:04.595 ServerApp] wrote error: 'Forbidden'
    Traceback (most recent call last):
      File "/home/cbel/Desktop/YIHAN/venv/lib/python3.8/site-packages/tornado/web.py", line 1788, in _execute
        result = method(*self.path_args, **self.path_kwargs)
      File "/home/cbel/Desktop/YIHAN/venv/lib/python3.8/site-packages/tornado/web.py", line 3289, in wrapper
        url = self.get_login_url()
      File "/home/cbel/Desktop/YIHAN/venv/lib/python3.8/site-packages/jupyter_server/base/handlers.py", line 783, in get_login_url
        raise web.HTTPError(403)
    tornado.web.HTTPError: HTTP 403: Forbidden
[W 2025-03-22 15:32:04.595 ServerApp] 403 GET /api/kernelspecs?1742628724592 (@127.0.0.1) 0.67ms referer=None
[W 2025-03-22 15:32:04.596 ServerApp] wrote error: 'Forbidden'
    Traceback (most recent call last):
      File "/home/cbel/Desktop/YIHAN/venv/lib/python3.8/site-packages/tornado/web.py", line 1788, in _execute
        result = method(*self.path_args, **self.path_kwargs)
      File "/home/cbel/Desktop/YIHAN/venv/lib/python3.8/site-packages/tornado/web.py", line 3289, in wrapper
        url = self.get_login_url()
      File "/home/cbel/Desktop/YIHAN/venv/lib/python3.8/site-packages/jupyter_server/base/handlers.py", line 783, in get_login_url
        raise web.HTTPError(403)
    tornado.web.HTTPError: HTTP 403: Forbidden
[W 2025-03-22 15:32:04.596 ServerApp] 403 GET /api/kernels?1742628724593 (@127.0.0.1) 0.87ms referer=None
[W 2025-03-22 15:32:04.596 ServerApp] wrote error: 'Forbidden'
    Traceback (most recent call last):
      File "/home/cbel/Desktop/YIHAN/venv/lib/python3.8/site-packages/tornado/web.py", line 1788, in _execute
        result = method(*self.path_args, **self.path_kwargs)
      File "/home/cbel/Desktop/YIHAN/venv/lib/python3.8/site-packages/tornado/web.py", line 3289, in wrapper
        url = self.get_login_url()
      File "/home/cbel/Desktop/YIHAN/venv/lib/python3.8/site-packages/jupyter_server/base/handlers.py", line 783, in get_login_url
        raise web.HTTPError(403)
    tornado.web.HTTPError: HTTP 403: Forbidden
[W 2025-03-22 15:32:04.597 ServerApp] 403 GET /api/kernelspecs?1742628724593 (@127.0.0.1) 1.04ms referer=None
[W 2025-03-22 15:32:04.597 ServerApp] wrote error: 'Forbidden'
    Traceback (most recent call last):
      File "/home/cbel/Desktop/YIHAN/venv/lib/python3.8/site-packages/tornado/web.py", line 1788, in _execute
        result = method(*self.path_args, **self.path_kwargs)
      File "/home/cbel/Desktop/YIHAN/venv/lib/python3.8/site-packages/tornado/web.py", line 3289, in wrapper
        url = self.get_login_url()
      File "/home/cbel/Desktop/YIHAN/venv/lib/python3.8/site-packages/jupyter_server/base/handlers.py", line 783, in get_login_url
        raise web.HTTPError(403)
    tornado.web.HTTPError: HTTP 403: Forbidden
[W 2025-03-22 15:32:04.597 ServerApp] 403 GET /api/kernels?1742628724593 (@127.0.0.1) 1.23ms referer=None
[W 2025-03-22 15:32:04.657 ServerApp] wrote error: 'Forbidden'
    Traceback (most recent call last):
      File "/home/cbel/Desktop/YIHAN/venv/lib/python3.8/site-packages/tornado/web.py", line 1788, in _execute
        result = method(*self.path_args, **self.path_kwargs)
      File "/home/cbel/Desktop/YIHAN/venv/lib/python3.8/site-packages/tornado/web.py", line 3289, in wrapper
        url = self.get_login_url()
      File "/home/cbel/Desktop/YIHAN/venv/lib/python3.8/site-packages/jupyter_server/base/handlers.py", line 783, in get_login_url
        raise web.HTTPError(403)
    tornado.web.HTTPError: HTTP 403: Forbidden
[W 2025-03-22 15:32:04.657 ServerApp] 403 GET /api/kernels?1742628724595 (@127.0.0.1) 0.65ms referer=None
[W 2025-03-22 15:32:04.657 ServerApp] wrote error: 'Forbidden'
    Traceback (most recent call last):
      File "/home/cbel/Desktop/YIHAN/venv/lib/python3.8/site-packages/tornado/web.py", line 1788, in _execute
        result = method(*self.path_args, **self.path_kwargs)
      File "/home/cbel/Desktop/YIHAN/venv/lib/python3.8/site-packages/tornado/web.py", line 3289, in wrapper
        url = self.get_login_url()
      File "/home/cbel/Desktop/YIHAN/venv/lib/python3.8/site-packages/jupyter_server/base/handlers.py", line 783, in get_login_url
        raise web.HTTPError(403)
    tornado.web.HTTPError: HTTP 403: Forbidden
[W 2025-03-22 15:32:04.658 ServerApp] 403 GET /api/sessions?1742628724595 (@127.0.0.1) 0.76ms referer=None
[W 2025-03-22 15:32:04.658 ServerApp] wrote error: 'Forbidden'
    Traceback (most recent call last):
      File "/home/cbel/Desktop/YIHAN/venv/lib/python3.8/site-packages/tornado/web.py", line 1788, in _execute
        result = method(*self.path_args, **self.path_kwargs)
      File "/home/cbel/Desktop/YIHAN/venv/lib/python3.8/site-packages/tornado/web.py", line 3289, in wrapper
        url = self.get_login_url()
      File "/home/cbel/Desktop/YIHAN/venv/lib/python3.8/site-packages/jupyter_server/base/handlers.py", line 783, in get_login_url
        raise web.HTTPError(403)
    tornado.web.HTTPError: HTTP 403: Forbidden
[W 2025-03-22 15:32:04.658 ServerApp] 403 GET /api/kernels?1742628724596 (@127.0.0.1) 1.00ms referer=None
[W 2025-03-22 15:32:04.658 ServerApp] wrote error: 'Forbidden'
    Traceback (most recent call last):
      File "/home/cbel/Desktop/YIHAN/venv/lib/python3.8/site-packages/tornado/web.py", line 1788, in _execute
        result = method(*self.path_args, **self.path_kwargs)
      File "/home/cbel/Desktop/YIHAN/venv/lib/python3.8/site-packages/tornado/web.py", line 3289, in wrapper
        url = self.get_login_url()
      File "/home/cbel/Desktop/YIHAN/venv/lib/python3.8/site-packages/jupyter_server/base/handlers.py", line 783, in get_login_url
        raise web.HTTPError(403)
    tornado.web.HTTPError: HTTP 403: Forbidden
[W 2025-03-22 15:32:04.659 ServerApp] 403 GET /api/sessions?1742628724596 (@127.0.0.1) 1.25ms referer=None
[W 2025-03-22 15:32:04.670 ServerApp] wrote error: 'Forbidden'
    Traceback (most recent call last):
      File "/home/cbel/Desktop/YIHAN/venv/lib/python3.8/site-packages/tornado/web.py", line 1788, in _execute
        result = method(*self.path_args, **self.path_kwargs)
      File "/home/cbel/Desktop/YIHAN/venv/lib/python3.8/site-packages/tornado/web.py", line 3289, in wrapper
        url = self.get_login_url()
      File "/home/cbel/Desktop/YIHAN/venv/lib/python3.8/site-packages/jupyter_server/base/handlers.py", line 783, in get_login_url
        raise web.HTTPError(403)
    tornado.web.HTTPError: HTTP 403: Forbidden
[W 2025-03-22 15:32:04.670 ServerApp] 403 GET /api/kernelspecs?1742628724656 (@127.0.0.1) 0.64ms referer=None
[W 2025-03-22 15:32:04.671 ServerApp] wrote error: 'Forbidden'
    Traceback (most recent call last):
      File "/home/cbel/Desktop/YIHAN/venv/lib/python3.8/site-packages/tornado/web.py", line 1788, in _execute
        result = method(*self.path_args, **self.path_kwargs)
      File "/home/cbel/Desktop/YIHAN/venv/lib/python3.8/site-packages/tornado/web.py", line 3289, in wrapper
        url = self.get_login_url()
      File "/home/cbel/Desktop/YIHAN/venv/lib/python3.8/site-packages/jupyter_server/base/handlers.py", line 783, in get_login_url
        raise web.HTTPError(403)
    tornado.web.HTTPError: HTTP 403: Forbidden
[W 2025-03-22 15:32:04.671 ServerApp] 403 GET /api/kernelspecs?1742628724657 (@127.0.0.1) 0.86ms referer=None
[I 2025-03-22 15:32:04.671 ServerApp] 302 GET / (@127.0.0.1) 0.19ms
[I 2025-03-22 15:32:04.675 JupyterNotebookApp] 302 GET /tree? (@127.0.0.1) 0.33ms
[W 2025-03-22 15:32:04.808 ServerApp] wrote error: 'Forbidden'
    Traceback (most recent call last):
      File "/home/cbel/Desktop/YIHAN/venv/lib/python3.8/site-packages/tornado/web.py", line 1788, in _execute
        result = method(*self.path_args, **self.path_kwargs)
      File "/home/cbel/Desktop/YIHAN/venv/lib/python3.8/site-packages/tornado/web.py", line 3289, in wrapper
        url = self.get_login_url()
      File "/home/cbel/Desktop/YIHAN/venv/lib/python3.8/site-packages/jupyter_server/base/handlers.py", line 783, in get_login_url
        raise web.HTTPError(403)
    tornado.web.HTTPError: HTTP 403: Forbidden
[W 2025-03-22 15:32:04.809 ServerApp] 403 GET /api/kernelspecs?1742628724806 (@127.0.0.1) 0.73ms referer=None
[W 2025-03-22 15:32:04.810 ServerApp] wrote error: 'Forbidden'
    Traceback (most recent call last):
      File "/home/cbel/Desktop/YIHAN/venv/lib/python3.8/site-packages/tornado/web.py", line 1788, in _execute
        result = method(*self.path_args, **self.path_kwargs)
      File "/home/cbel/Desktop/YIHAN/venv/lib/python3.8/site-packages/tornado/web.py", line 3289, in wrapper
        url = self.get_login_url()
      File "/home/cbel/Desktop/YIHAN/venv/lib/python3.8/site-packages/jupyter_server/base/handlers.py", line 783, in get_login_url
        raise web.HTTPError(403)
    tornado.web.HTTPError: HTTP 403: Forbidden
[W 2025-03-22 15:32:04.810 ServerApp] 403 GET /api/kernels?1742628724807 (@127.0.0.1) 0.58ms referer=None
[W 2025-03-22 15:32:04.811 ServerApp] wrote error: 'Forbidden'
    Traceback (most recent call last):
      File "/home/cbel/Desktop/YIHAN/venv/lib/python3.8/site-packages/tornado/web.py", line 1788, in _execute
        result = method(*self.path_args, **self.path_kwargs)
      File "/home/cbel/Desktop/YIHAN/venv/lib/python3.8/site-packages/tornado/web.py", line 3289, in wrapper
        url = self.get_login_url()
      File "/home/cbel/Desktop/YIHAN/venv/lib/python3.8/site-packages/jupyter_server/base/handlers.py", line 783, in get_login_url
        raise web.HTTPError(403)
    tornado.web.HTTPError: HTTP 403: Forbidden
[W 2025-03-22 15:32:04.811 ServerApp] 403 GET /api/kernels?1742628724808 (@127.0.0.1) 0.47ms referer=None
[W 2025-03-22 15:32:04.811 ServerApp] wrote error: 'Forbidden'
    Traceback (most recent call last):
      File "/home/cbel/Desktop/YIHAN/venv/lib/python3.8/site-packages/tornado/web.py", line 1788, in _execute
        result = method(*self.path_args, **self.path_kwargs)
      File "/home/cbel/Desktop/YIHAN/venv/lib/python3.8/site-packages/tornado/web.py", line 3289, in wrapper
        url = self.get_login_url()
      File "/home/cbel/Desktop/YIHAN/venv/lib/python3.8/site-packages/jupyter_server/base/handlers.py", line 783, in get_login_url
        raise web.HTTPError(403)
    tornado.web.HTTPError: HTTP 403: Forbidden
[W 2025-03-22 15:32:04.811 ServerApp] 403 GET /api/sessions?1742628724809 (@127.0.0.1) 0.47ms referer=None
[W 2025-03-22 15:32:04.814 ServerApp] wrote error: 'Forbidden'
    Traceback (most recent call last):
      File "/home/cbel/Desktop/YIHAN/venv/lib/python3.8/site-packages/tornado/web.py", line 1788, in _execute
        result = method(*self.path_args, **self.path_kwargs)
      File "/home/cbel/Desktop/YIHAN/venv/lib/python3.8/site-packages/tornado/web.py", line 3289, in wrapper
        url = self.get_login_url()
      File "/home/cbel/Desktop/YIHAN/venv/lib/python3.8/site-packages/jupyter_server/base/handlers.py", line 783, in get_login_url
        raise web.HTTPError(403)
    tornado.web.HTTPError: HTTP 403: Forbidden
[W 2025-03-22 15:32:04.815 ServerApp] 403 GET /api/kernelspecs?1742628724812 (@127.0.0.1) 0.49ms referer=None
[I 2025-03-22 15:32:05.721 ServerApp] User a9640ccac3a2493a94acf58a6827e199 logged in.
[I 2025-03-22 15:32:05.722 ServerApp] 302 POST /login? (a9640ccac3a2493a94acf58a6827e199@127.0.0.1) 0.65ms
[I 2025-03-22 15:32:05.778 ServerApp] Connecting to kernel c2f5cbbe-5426-4551-b160-3a95988a0bb2.
[I 2025-03-22 15:32:05.890 ServerApp] 302 GET / (@127.0.0.1) 0.30ms
[I 2025-03-22 15:32:05.895 JupyterNotebookApp] 302 GET /tree? (@127.0.0.1) 0.98ms
[I 2025-03-22 15:32:07.138 ServerApp] User e417af8862e343b1beeae4ae7f7fad42 logged in.
[I 2025-03-22 15:32:07.139 ServerApp] 302 POST /login? (e417af8862e343b1beeae4ae7f7fad42@127.0.0.1) 0.90ms
2025-03-22 15:32:14.075164: I tensorflow/stream_executor/cuda/cuda_gpu_executor.cc:939] successful NUMA node read from SysFS had negative value (-1), but there must be at least one NUMA node, so returning NUMA node zero
2025-03-22 15:32:14.099919: I tensorflow/stream_executor/cuda/cuda_gpu_executor.cc:939] successful NUMA node read from SysFS had negative value (-1), but there must be at least one NUMA node, so returning NUMA node zero
2025-03-22 15:32:14.100432: I tensorflow/stream_executor/cuda/cuda_gpu_executor.cc:939] successful NUMA node read from SysFS had negative value (-1), but there must be at least one NUMA node, so returning NUMA node zero
2025-03-22 15:32:14.110303: I tensorflow/core/platform/cpu_feature_guard.cc:151] This TensorFlow binary is optimized with oneAPI Deep Neural Network Library (oneDNN) to use the following CPU instructions in performance-critical operations:  AVX2 FMA
To enable them in other operations, rebuild TensorFlow with the appropriate compiler flags.
2025-03-22 15:32:14.111261: I tensorflow/stream_executor/cuda/cuda_gpu_executor.cc:939] successful NUMA node read from SysFS had negative value (-1), but there must be at least one NUMA node, so returning NUMA node zero
2025-03-22 15:32:14.111932: I tensorflow/stream_executor/cuda/cuda_gpu_executor.cc:939] successful NUMA node read from SysFS had negative value (-1), but there must be at least one NUMA node, so returning NUMA node zero
2025-03-22 15:32:14.112485: I tensorflow/stream_executor/cuda/cuda_gpu_executor.cc:939] successful NUMA node read from SysFS had negative value (-1), but there must be at least one NUMA node, so returning NUMA node zero
2025-03-22 15:32:14.627060: I tensorflow/stream_executor/cuda/cuda_gpu_executor.cc:939] successful NUMA node read from SysFS had negative value (-1), but there must be at least one NUMA node, so returning NUMA node zero
2025-03-22 15:32:14.627554: I tensorflow/stream_executor/cuda/cuda_gpu_executor.cc:939] successful NUMA node read from SysFS had negative value (-1), but there must be at least one NUMA node, so returning NUMA node zero
2025-03-22 15:32:14.627998: I tensorflow/stream_executor/cuda/cuda_gpu_executor.cc:939] successful NUMA node read from SysFS had negative value (-1), but there must be at least one NUMA node, so returning NUMA node zero
2025-03-22 15:32:14.628420: I tensorflow/core/common_runtime/gpu/gpu_process_state.cc:214] Using CUDA malloc Async allocator for GPU: 0
2025-03-22 15:32:14.629019: I tensorflow/core/common_runtime/gpu/gpu_device.cc:1525] Created device /job:localhost/replica:0/task:0/device:GPU:0 with 18432 MB memory:  -> device: 0, name: NVIDIA GeForce RTX 3090, pci bus id: 0000:01:00.0, compute capability: 8.6
2025-03-22 15:37:12.639494: I tensorflow/stream_executor/cuda/cuda_dnn.cc:366] Loaded cuDNN version 8202
[I 2025-03-22 17:50:11.160 ServerApp] Starting buffering for c2f5cbbe-5426-4551-b160-3a95988a0bb2:7e2c11e0-8e44-40a8-8fea-54ea28c45b60
[I 2025-03-22 17:50:53.040 ServerApp] 302 GET / (@127.0.0.1) 0.26ms
[I 2025-03-22 17:50:53.040 ServerApp] 302 GET / (@127.0.0.1) 0.19ms
[I 2025-03-22 17:50:53.045 JupyterNotebookApp] 302 GET /tree? (@127.0.0.1) 0.39ms
[I 2025-03-22 17:50:53.048 JupyterNotebookApp] 302 GET /tree? (@127.0.0.1) 0.35ms
[W 2025-03-22 17:50:53.785 ServerApp] wrote error: 'Forbidden'
    Traceback (most recent call last):
      File "/home/cbel/Desktop/YIHAN/venv/lib/python3.8/site-packages/tornado/web.py", line 1788, in _execute
        result = method(*self.path_args, **self.path_kwargs)
      File "/home/cbel/Desktop/YIHAN/venv/lib/python3.8/site-packages/tornado/web.py", line 3289, in wrapper
        url = self.get_login_url()
      File "/home/cbel/Desktop/YIHAN/venv/lib/python3.8/site-packages/jupyter_server/base/handlers.py", line 783, in get_login_url
        raise web.HTTPError(403)
    tornado.web.HTTPError: HTTP 403: Forbidden
[W 2025-03-22 17:50:53.785 ServerApp] 403 GET /api/kernelspecs?1742637053782 (@127.0.0.1) 0.82ms referer=None
[W 2025-03-22 17:50:53.786 ServerApp] wrote error: 'Forbidden'
    Traceback (most recent call last):
      File "/home/cbel/Desktop/YIHAN/venv/lib/python3.8/site-packages/tornado/web.py", line 1788, in _execute
        result = method(*self.path_args, **self.path_kwargs)
      File "/home/cbel/Desktop/YIHAN/venv/lib/python3.8/site-packages/tornado/web.py", line 3289, in wrapper
        url = self.get_login_url()
      File "/home/cbel/Desktop/YIHAN/venv/lib/python3.8/site-packages/jupyter_server/base/handlers.py", line 783, in get_login_url
        raise web.HTTPError(403)
    tornado.web.HTTPError: HTTP 403: Forbidden
[W 2025-03-22 17:50:53.786 ServerApp] 403 GET /api/kernels?1742637053783 (@127.0.0.1) 0.53ms referer=None
[W 2025-03-22 17:50:53.793 ServerApp] wrote error: 'Forbidden'
    Traceback (most recent call last):
      File "/home/cbel/Desktop/YIHAN/venv/lib/python3.8/site-packages/tornado/web.py", line 1788, in _execute
        result = method(*self.path_args, **self.path_kwargs)
      File "/home/cbel/Desktop/YIHAN/venv/lib/python3.8/site-packages/tornado/web.py", line 3289, in wrapper
        url = self.get_login_url()
      File "/home/cbel/Desktop/YIHAN/venv/lib/python3.8/site-packages/jupyter_server/base/handlers.py", line 783, in get_login_url
        raise web.HTTPError(403)
    tornado.web.HTTPError: HTTP 403: Forbidden
[W 2025-03-22 17:50:53.793 ServerApp] 403 GET /api/kernels?1742637053785 (@127.0.0.1) 0.60ms referer=None
[W 2025-03-22 17:50:53.794 ServerApp] wrote error: 'Forbidden'
    Traceback (most recent call last):
      File "/home/cbel/Desktop/YIHAN/venv/lib/python3.8/site-packages/tornado/web.py", line 1788, in _execute
        result = method(*self.path_args, **self.path_kwargs)
      File "/home/cbel/Desktop/YIHAN/venv/lib/python3.8/site-packages/tornado/web.py", line 3289, in wrapper
        url = self.get_login_url()
      File "/home/cbel/Desktop/YIHAN/venv/lib/python3.8/site-packages/jupyter_server/base/handlers.py", line 783, in get_login_url
        raise web.HTTPError(403)
    tornado.web.HTTPError: HTTP 403: Forbidden
[W 2025-03-22 17:50:53.794 ServerApp] 403 GET /api/sessions?1742637053786 (@127.0.0.1) 0.61ms referer=None
[W 2025-03-22 17:50:53.795 ServerApp] wrote error: 'Forbidden'
    Traceback (most recent call last):
      File "/home/cbel/Desktop/YIHAN/venv/lib/python3.8/site-packages/tornado/web.py", line 1788, in _execute
        result = method(*self.path_args, **self.path_kwargs)
      File "/home/cbel/Desktop/YIHAN/venv/lib/python3.8/site-packages/tornado/web.py", line 3289, in wrapper
        url = self.get_login_url()
      File "/home/cbel/Desktop/YIHAN/venv/lib/python3.8/site-packages/jupyter_server/base/handlers.py", line 783, in get_login_url
        raise web.HTTPError(403)
    tornado.web.HTTPError: HTTP 403: Forbidden
[W 2025-03-22 17:50:53.795 ServerApp] 403 GET /api/kernelspecs?1742637053793 (@127.0.0.1) 0.42ms referer=None
[I 2025-03-22 17:50:53.801 ServerApp] 302 GET / (@127.0.0.1) 0.21ms
[I 2025-03-22 17:50:53.802 JupyterNotebookApp] 302 GET /tree? (@127.0.0.1) 0.31ms
[W 2025-03-22 17:50:54.157 ServerApp] wrote error: 'Forbidden'
    Traceback (most recent call last):
      File "/home/cbel/Desktop/YIHAN/venv/lib/python3.8/site-packages/tornado/web.py", line 1788, in _execute
        result = method(*self.path_args, **self.path_kwargs)
      File "/home/cbel/Desktop/YIHAN/venv/lib/python3.8/site-packages/tornado/web.py", line 3289, in wrapper
        url = self.get_login_url()
      File "/home/cbel/Desktop/YIHAN/venv/lib/python3.8/site-packages/jupyter_server/base/handlers.py", line 783, in get_login_url
        raise web.HTTPError(403)
    tornado.web.HTTPError: HTTP 403: Forbidden
[W 2025-03-22 17:50:54.157 ServerApp] 403 GET /api/kernelspecs?1742637054154 (@127.0.0.1) 0.65ms referer=None
[W 2025-03-22 17:50:54.166 ServerApp] wrote error: 'Forbidden'
    Traceback (most recent call last):
      File "/home/cbel/Desktop/YIHAN/venv/lib/python3.8/site-packages/tornado/web.py", line 1788, in _execute
        result = method(*self.path_args, **self.path_kwargs)
      File "/home/cbel/Desktop/YIHAN/venv/lib/python3.8/site-packages/tornado/web.py", line 3289, in wrapper
        url = self.get_login_url()
      File "/home/cbel/Desktop/YIHAN/venv/lib/python3.8/site-packages/jupyter_server/base/handlers.py", line 783, in get_login_url
        raise web.HTTPError(403)
    tornado.web.HTTPError: HTTP 403: Forbidden
[W 2025-03-22 17:50:54.167 ServerApp] 403 GET /api/kernels?1742637054155 (@127.0.0.1) 0.71ms referer=None
[W 2025-03-22 17:50:54.167 ServerApp] wrote error: 'Forbidden'
    Traceback (most recent call last):
      File "/home/cbel/Desktop/YIHAN/venv/lib/python3.8/site-packages/tornado/web.py", line 1788, in _execute
        result = method(*self.path_args, **self.path_kwargs)
      File "/home/cbel/Desktop/YIHAN/venv/lib/python3.8/site-packages/tornado/web.py", line 3289, in wrapper
        url = self.get_login_url()
      File "/home/cbel/Desktop/YIHAN/venv/lib/python3.8/site-packages/jupyter_server/base/handlers.py", line 783, in get_login_url
        raise web.HTTPError(403)
    tornado.web.HTTPError: HTTP 403: Forbidden
[W 2025-03-22 17:50:54.167 ServerApp] 403 GET /api/kernelspecs?1742637054155 (@127.0.0.1) 0.53ms referer=None
[W 2025-03-22 17:50:54.168 ServerApp] wrote error: 'Forbidden'
    Traceback (most recent call last):
      File "/home/cbel/Desktop/YIHAN/venv/lib/python3.8/site-packages/tornado/web.py", line 1788, in _execute
        result = method(*self.path_args, **self.path_kwargs)
      File "/home/cbel/Desktop/YIHAN/venv/lib/python3.8/site-packages/tornado/web.py", line 3289, in wrapper
        url = self.get_login_url()
      File "/home/cbel/Desktop/YIHAN/venv/lib/python3.8/site-packages/jupyter_server/base/handlers.py", line 783, in get_login_url
        raise web.HTTPError(403)
    tornado.web.HTTPError: HTTP 403: Forbidden
[W 2025-03-22 17:50:54.168 ServerApp] 403 GET /api/kernels?1742637054155 (@127.0.0.1) 0.61ms referer=None
[W 2025-03-22 17:50:54.168 ServerApp] wrote error: 'Forbidden'
    Traceback (most recent call last):
      File "/home/cbel/Desktop/YIHAN/venv/lib/python3.8/site-packages/tornado/web.py", line 1788, in _execute
        result = method(*self.path_args, **self.path_kwargs)
      File "/home/cbel/Desktop/YIHAN/venv/lib/python3.8/site-packages/tornado/web.py", line 3289, in wrapper
        url = self.get_login_url()
      File "/home/cbel/Desktop/YIHAN/venv/lib/python3.8/site-packages/jupyter_server/base/handlers.py", line 783, in get_login_url
        raise web.HTTPError(403)
    tornado.web.HTTPError: HTTP 403: Forbidden
[W 2025-03-22 17:50:54.168 ServerApp] 403 GET /api/kernels?1742637054157 (@127.0.0.1) 0.89ms referer=None
[W 2025-03-22 17:50:54.169 ServerApp] wrote error: 'Forbidden'
    Traceback (most recent call last):
      File "/home/cbel/Desktop/YIHAN/venv/lib/python3.8/site-packages/tornado/web.py", line 1788, in _execute
        result = method(*self.path_args, **self.path_kwargs)
      File "/home/cbel/Desktop/YIHAN/venv/lib/python3.8/site-packages/tornado/web.py", line 3289, in wrapper
        url = self.get_login_url()
      File "/home/cbel/Desktop/YIHAN/venv/lib/python3.8/site-packages/jupyter_server/base/handlers.py", line 783, in get_login_url
        raise web.HTTPError(403)
    tornado.web.HTTPError: HTTP 403: Forbidden
[W 2025-03-22 17:50:54.169 ServerApp] 403 GET /api/sessions?1742637054157 (@127.0.0.1) 0.49ms referer=None
[W 2025-03-22 17:50:54.170 ServerApp] wrote error: 'Forbidden'
    Traceback (most recent call last):
      File "/home/cbel/Desktop/YIHAN/venv/lib/python3.8/site-packages/tornado/web.py", line 1788, in _execute
        result = method(*self.path_args, **self.path_kwargs)
      File "/home/cbel/Desktop/YIHAN/venv/lib/python3.8/site-packages/tornado/web.py", line 3289, in wrapper
        url = self.get_login_url()
      File "/home/cbel/Desktop/YIHAN/venv/lib/python3.8/site-packages/jupyter_server/base/handlers.py", line 783, in get_login_url
        raise web.HTTPError(403)
    tornado.web.HTTPError: HTTP 403: Forbidden
[W 2025-03-22 17:50:54.170 ServerApp] 403 GET /api/kernels?1742637054161 (@127.0.0.1) 0.68ms referer=None
[W 2025-03-22 17:50:54.170 ServerApp] wrote error: 'Forbidden'
    Traceback (most recent call last):
      File "/home/cbel/Desktop/YIHAN/venv/lib/python3.8/site-packages/tornado/web.py", line 1788, in _execute
        result = method(*self.path_args, **self.path_kwargs)
      File "/home/cbel/Desktop/YIHAN/venv/lib/python3.8/site-packages/tornado/web.py", line 3289, in wrapper
        url = self.get_login_url()
      File "/home/cbel/Desktop/YIHAN/venv/lib/python3.8/site-packages/jupyter_server/base/handlers.py", line 783, in get_login_url
        raise web.HTTPError(403)
    tornado.web.HTTPError: HTTP 403: Forbidden
[W 2025-03-22 17:50:54.170 ServerApp] 403 GET /api/sessions?1742637054162 (@127.0.0.1) 0.94ms referer=None
[W 2025-03-22 17:50:54.170 ServerApp] wrote error: 'Forbidden'
    Traceback (most recent call last):
      File "/home/cbel/Desktop/YIHAN/venv/lib/python3.8/site-packages/tornado/web.py", line 1788, in _execute
        result = method(*self.path_args, **self.path_kwargs)
      File "/home/cbel/Desktop/YIHAN/venv/lib/python3.8/site-packages/tornado/web.py", line 3289, in wrapper
        url = self.get_login_url()
      File "/home/cbel/Desktop/YIHAN/venv/lib/python3.8/site-packages/jupyter_server/base/handlers.py", line 783, in get_login_url
        raise web.HTTPError(403)
    tornado.web.HTTPError: HTTP 403: Forbidden
[W 2025-03-22 17:50:54.171 ServerApp] 403 GET /api/kernelspecs?1742637054162 (@127.0.0.1) 1.20ms referer=None
[I 2025-03-22 17:50:54.232 ServerApp] 302 GET / (@127.0.0.1) 0.26ms
[I 2025-03-22 17:50:54.236 JupyterNotebookApp] 302 GET /tree? (@127.0.0.1) 0.38ms
[W 2025-03-22 17:50:54.236 ServerApp] wrote error: 'Forbidden'
    Traceback (most recent call last):
      File "/home/cbel/Desktop/YIHAN/venv/lib/python3.8/site-packages/tornado/web.py", line 1788, in _execute
        result = method(*self.path_args, **self.path_kwargs)
      File "/home/cbel/Desktop/YIHAN/venv/lib/python3.8/site-packages/tornado/web.py", line 3289, in wrapper
        url = self.get_login_url()
      File "/home/cbel/Desktop/YIHAN/venv/lib/python3.8/site-packages/jupyter_server/base/handlers.py", line 783, in get_login_url
        raise web.HTTPError(403)
    tornado.web.HTTPError: HTTP 403: Forbidden
[W 2025-03-22 17:50:54.237 ServerApp] 403 GET /api/kernelspecs?1742637054230 (@127.0.0.1) 0.53ms referer=None
[W 2025-03-22 17:50:54.442 ServerApp] wrote error: 'Forbidden'
    Traceback (most recent call last):
      File "/home/cbel/Desktop/YIHAN/venv/lib/python3.8/site-packages/tornado/web.py", line 1788, in _execute
        result = method(*self.path_args, **self.path_kwargs)
      File "/home/cbel/Desktop/YIHAN/venv/lib/python3.8/site-packages/tornado/web.py", line 3289, in wrapper
        url = self.get_login_url()
      File "/home/cbel/Desktop/YIHAN/venv/lib/python3.8/site-packages/jupyter_server/base/handlers.py", line 783, in get_login_url
        raise web.HTTPError(403)
    tornado.web.HTTPError: HTTP 403: Forbidden
[W 2025-03-22 17:50:54.442 ServerApp] 403 GET /api/kernelspecs?1742637054440 (@127.0.0.1) 0.93ms referer=None
[W 2025-03-22 17:50:54.443 ServerApp] wrote error: 'Forbidden'
    Traceback (most recent call last):
      File "/home/cbel/Desktop/YIHAN/venv/lib/python3.8/site-packages/tornado/web.py", line 1788, in _execute
        result = method(*self.path_args, **self.path_kwargs)
      File "/home/cbel/Desktop/YIHAN/venv/lib/python3.8/site-packages/tornado/web.py", line 3289, in wrapper
        url = self.get_login_url()
      File "/home/cbel/Desktop/YIHAN/venv/lib/python3.8/site-packages/jupyter_server/base/handlers.py", line 783, in get_login_url
        raise web.HTTPError(403)
    tornado.web.HTTPError: HTTP 403: Forbidden
[W 2025-03-22 17:50:54.443 ServerApp] 403 GET /api/kernels?1742637054441 (@127.0.0.1) 1.06ms referer=None
[W 2025-03-22 17:50:54.445 ServerApp] wrote error: 'Forbidden'
    Traceback (most recent call last):
      File "/home/cbel/Desktop/YIHAN/venv/lib/python3.8/site-packages/tornado/web.py", line 1788, in _execute
        result = method(*self.path_args, **self.path_kwargs)
      File "/home/cbel/Desktop/YIHAN/venv/lib/python3.8/site-packages/tornado/web.py", line 3289, in wrapper
        url = self.get_login_url()
      File "/home/cbel/Desktop/YIHAN/venv/lib/python3.8/site-packages/jupyter_server/base/handlers.py", line 783, in get_login_url
        raise web.HTTPError(403)
    tornado.web.HTTPError: HTTP 403: Forbidden
[W 2025-03-22 17:50:54.445 ServerApp] 403 GET /api/kernels?1742637054442 (@127.0.0.1) 0.60ms referer=None
[W 2025-03-22 17:50:54.445 ServerApp] wrote error: 'Forbidden'
    Traceback (most recent call last):
      File "/home/cbel/Desktop/YIHAN/venv/lib/python3.8/site-packages/tornado/web.py", line 1788, in _execute
        result = method(*self.path_args, **self.path_kwargs)
      File "/home/cbel/Desktop/YIHAN/venv/lib/python3.8/site-packages/tornado/web.py", line 3289, in wrapper
        url = self.get_login_url()
      File "/home/cbel/Desktop/YIHAN/venv/lib/python3.8/site-packages/jupyter_server/base/handlers.py", line 783, in get_login_url
        raise web.HTTPError(403)
    tornado.web.HTTPError: HTTP 403: Forbidden
[W 2025-03-22 17:50:54.446 ServerApp] 403 GET /api/sessions?1742637054443 (@127.0.0.1) 0.91ms referer=None
[W 2025-03-22 17:50:54.447 ServerApp] wrote error: 'Forbidden'
    Traceback (most recent call last):
      File "/home/cbel/Desktop/YIHAN/venv/lib/python3.8/site-packages/tornado/web.py", line 1788, in _execute
        result = method(*self.path_args, **self.path_kwargs)
      File "/home/cbel/Desktop/YIHAN/venv/lib/python3.8/site-packages/tornado/web.py", line 3289, in wrapper
        url = self.get_login_url()
      File "/home/cbel/Desktop/YIHAN/venv/lib/python3.8/site-packages/jupyter_server/base/handlers.py", line 783, in get_login_url
        raise web.HTTPError(403)
    tornado.web.HTTPError: HTTP 403: Forbidden
[W 2025-03-22 17:50:54.447 ServerApp] 403 GET /api/kernelspecs?1742637054445 (@127.0.0.1) 0.66ms referer=None
[I 2025-03-22 17:50:58.557 ServerApp] User 14c617eb6e5a49a9bc27e888166b19c5 logged in.
[I 2025-03-22 17:50:58.558 ServerApp] 302 POST /login? (14c617eb6e5a49a9bc27e888166b19c5@127.0.0.1) 0.59ms
[I 2025-03-22 17:50:58.584 ServerApp] Connecting to kernel c2f5cbbe-5426-4551-b160-3a95988a0bb2.
[I 2025-03-22 17:50:58.694 ServerApp] 302 GET / (@127.0.0.1) 0.24ms
[I 2025-03-22 17:50:58.699 JupyterNotebookApp] 302 GET /tree? (@127.0.0.1) 0.35ms
[I 2025-03-22 17:50:59.683 ServerApp] User 94288054f31441bd8e2fc02d491cb57b logged in.
[I 2025-03-22 17:50:59.683 ServerApp] 302 POST /login? (94288054f31441bd8e2fc02d491cb57b@127.0.0.1) 0.79ms
[I 2025-03-22 17:56:15.815 ServerApp] AsyncIOLoopKernelRestarter: restarting kernel (1/5), keep random ports
[W 2025-03-22 17:56:15.816 ServerApp] kernel c2f5cbbe-5426-4551-b160-3a95988a0bb2 restarted
[I 2025-03-22 17:56:15.853 ServerApp] Starting buffering for c2f5cbbe-5426-4551-b160-3a95988a0bb2:0186a735-938e-4e20-a9d5-955ee798ccc5
[I 2025-03-22 17:56:15.874 ServerApp] Connecting to kernel c2f5cbbe-5426-4551-b160-3a95988a0bb2.
[I 2025-03-22 17:56:15.874 ServerApp] Restoring connection for c2f5cbbe-5426-4551-b160-3a95988a0bb2:0186a735-938e-4e20-a9d5-955ee798ccc5
[I 2025-03-22 17:57:50.100 ServerApp] Kernel restarted: c2f5cbbe-5426-4551-b160-3a95988a0bb2
[I 2025-03-22 17:57:50.102 ServerApp] Starting buffering for c2f5cbbe-5426-4551-b160-3a95988a0bb2:0186a735-938e-4e20-a9d5-955ee798ccc5
[I 2025-03-22 17:57:50.105 ServerApp] Connecting to kernel c2f5cbbe-5426-4551-b160-3a95988a0bb2.
[I 2025-03-22 17:57:50.105 ServerApp] Restoring connection for c2f5cbbe-5426-4551-b160-3a95988a0bb2:0186a735-938e-4e20-a9d5-955ee798ccc5
2025-03-22 17:58:01.350335: I tensorflow/stream_executor/cuda/cuda_gpu_executor.cc:939] successful NUMA node read from SysFS had negative value (-1), but there must be at least one NUMA node, so returning NUMA node zero
2025-03-22 17:58:01.398178: I tensorflow/stream_executor/cuda/cuda_gpu_executor.cc:939] successful NUMA node read from SysFS had negative value (-1), but there must be at least one NUMA node, so returning NUMA node zero
2025-03-22 17:58:01.400834: I tensorflow/stream_executor/cuda/cuda_gpu_executor.cc:939] successful NUMA node read from SysFS had negative value (-1), but there must be at least one NUMA node, so returning NUMA node zero
2025-03-22 17:58:01.417620: I tensorflow/core/platform/cpu_feature_guard.cc:151] This TensorFlow binary is optimized with oneAPI Deep Neural Network Library (oneDNN) to use the following CPU instructions in performance-critical operations:  AVX2 FMA
To enable them in other operations, rebuild TensorFlow with the appropriate compiler flags.
2025-03-22 17:58:01.418444: I tensorflow/stream_executor/cuda/cuda_gpu_executor.cc:939] successful NUMA node read from SysFS had negative value (-1), but there must be at least one NUMA node, so returning NUMA node zero
2025-03-22 17:58:01.418950: I tensorflow/stream_executor/cuda/cuda_gpu_executor.cc:939] successful NUMA node read from SysFS had negative value (-1), but there must be at least one NUMA node, so returning NUMA node zero
2025-03-22 17:58:01.419409: I tensorflow/stream_executor/cuda/cuda_gpu_executor.cc:939] successful NUMA node read from SysFS had negative value (-1), but there must be at least one NUMA node, so returning NUMA node zero
2025-03-22 17:58:02.033299: I tensorflow/stream_executor/cuda/cuda_gpu_executor.cc:939] successful NUMA node read from SysFS had negative value (-1), but there must be at least one NUMA node, so returning NUMA node zero
2025-03-22 17:58:02.033799: I tensorflow/stream_executor/cuda/cuda_gpu_executor.cc:939] successful NUMA node read from SysFS had negative value (-1), but there must be at least one NUMA node, so returning NUMA node zero
2025-03-22 17:58:02.034252: I tensorflow/stream_executor/cuda/cuda_gpu_executor.cc:939] successful NUMA node read from SysFS had negative value (-1), but there must be at least one NUMA node, so returning NUMA node zero
2025-03-22 17:58:02.034674: I tensorflow/core/common_runtime/gpu/gpu_process_state.cc:214] Using CUDA malloc Async allocator for GPU: 0
2025-03-22 17:58:02.035274: I tensorflow/core/common_runtime/gpu/gpu_device.cc:1525] Created device /job:localhost/replica:0/task:0/device:GPU:0 with 18432 MB memory:  -> device: 0, name: NVIDIA GeForce RTX 3090, pci bus id: 0000:01:00.0, compute capability: 8.6
[I 2025-03-22 17:58:18.762 ServerApp] Kernel restarted: c2f5cbbe-5426-4551-b160-3a95988a0bb2
[I 2025-03-22 17:58:18.764 ServerApp] Starting buffering for c2f5cbbe-5426-4551-b160-3a95988a0bb2:0186a735-938e-4e20-a9d5-955ee798ccc5
[I 2025-03-22 17:58:18.767 ServerApp] Connecting to kernel c2f5cbbe-5426-4551-b160-3a95988a0bb2.
[I 2025-03-22 17:58:18.767 ServerApp] Restoring connection for c2f5cbbe-5426-4551-b160-3a95988a0bb2:0186a735-938e-4e20-a9d5-955ee798ccc5
2025-03-22 17:58:23.218302: I tensorflow/stream_executor/cuda/cuda_gpu_executor.cc:939] successful NUMA node read from SysFS had negative value (-1), but there must be at least one NUMA node, so returning NUMA node zero
2025-03-22 17:58:23.228078: I tensorflow/stream_executor/cuda/cuda_gpu_executor.cc:939] successful NUMA node read from SysFS had negative value (-1), but there must be at least one NUMA node, so returning NUMA node zero
2025-03-22 17:58:23.229160: I tensorflow/stream_executor/cuda/cuda_gpu_executor.cc:939] successful NUMA node read from SysFS had negative value (-1), but there must be at least one NUMA node, so returning NUMA node zero
2025-03-22 17:58:23.244088: I tensorflow/core/platform/cpu_feature_guard.cc:151] This TensorFlow binary is optimized with oneAPI Deep Neural Network Library (oneDNN) to use the following CPU instructions in performance-critical operations:  AVX2 FMA
To enable them in other operations, rebuild TensorFlow with the appropriate compiler flags.
2025-03-22 17:58:23.244560: I tensorflow/stream_executor/cuda/cuda_gpu_executor.cc:939] successful NUMA node read from SysFS had negative value (-1), but there must be at least one NUMA node, so returning NUMA node zero
2025-03-22 17:58:23.245083: I tensorflow/stream_executor/cuda/cuda_gpu_executor.cc:939] successful NUMA node read from SysFS had negative value (-1), but there must be at least one NUMA node, so returning NUMA node zero
2025-03-22 17:58:23.245541: I tensorflow/stream_executor/cuda/cuda_gpu_executor.cc:939] successful NUMA node read from SysFS had negative value (-1), but there must be at least one NUMA node, so returning NUMA node zero
2025-03-22 17:58:23.569715: I tensorflow/stream_executor/cuda/cuda_gpu_executor.cc:939] successful NUMA node read from SysFS had negative value (-1), but there must be at least one NUMA node, so returning NUMA node zero
2025-03-22 17:58:23.570222: I tensorflow/stream_executor/cuda/cuda_gpu_executor.cc:939] successful NUMA node read from SysFS had negative value (-1), but there must be at least one NUMA node, so returning NUMA node zero
2025-03-22 17:58:23.570667: I tensorflow/stream_executor/cuda/cuda_gpu_executor.cc:939] successful NUMA node read from SysFS had negative value (-1), but there must be at least one NUMA node, so returning NUMA node zero
2025-03-22 17:58:23.571090: I tensorflow/core/common_runtime/gpu/gpu_process_state.cc:214] Using CUDA malloc Async allocator for GPU: 0
2025-03-22 17:58:23.571506: I tensorflow/core/common_runtime/gpu/gpu_device.cc:1525] Created device /job:localhost/replica:0/task:0/device:GPU:0 with 18432 MB memory:  -> device: 0, name: NVIDIA GeForce RTX 3090, pci bus id: 0000:01:00.0, compute capability: 8.6
2025-03-22 18:02:31.655479: I tensorflow/stream_executor/cuda/cuda_dnn.cc:366] Loaded cuDNN version 8202
[I 2025-03-22 19:41:55.838 ServerApp] Kernel restarted: c2f5cbbe-5426-4551-b160-3a95988a0bb2
[I 2025-03-22 19:41:55.840 ServerApp] Starting buffering for c2f5cbbe-5426-4551-b160-3a95988a0bb2:0186a735-938e-4e20-a9d5-955ee798ccc5
[I 2025-03-22 19:41:55.844 ServerApp] Connecting to kernel c2f5cbbe-5426-4551-b160-3a95988a0bb2.
[I 2025-03-22 19:41:55.844 ServerApp] Restoring connection for c2f5cbbe-5426-4551-b160-3a95988a0bb2:0186a735-938e-4e20-a9d5-955ee798ccc5
2025-03-22 19:42:07.598328: I tensorflow/stream_executor/cuda/cuda_gpu_executor.cc:939] successful NUMA node read from SysFS had negative value (-1), but there must be at least one NUMA node, so returning NUMA node zero
2025-03-22 19:42:07.603362: I tensorflow/stream_executor/cuda/cuda_gpu_executor.cc:939] successful NUMA node read from SysFS had negative value (-1), but there must be at least one NUMA node, so returning NUMA node zero
2025-03-22 19:42:07.603906: I tensorflow/stream_executor/cuda/cuda_gpu_executor.cc:939] successful NUMA node read from SysFS had negative value (-1), but there must be at least one NUMA node, so returning NUMA node zero
2025-03-22 19:42:07.611550: I tensorflow/core/platform/cpu_feature_guard.cc:151] This TensorFlow binary is optimized with oneAPI Deep Neural Network Library (oneDNN) to use the following CPU instructions in performance-critical operations:  AVX2 FMA
To enable them in other operations, rebuild TensorFlow with the appropriate compiler flags.
2025-03-22 19:42:07.611999: I tensorflow/stream_executor/cuda/cuda_gpu_executor.cc:939] successful NUMA node read from SysFS had negative value (-1), but there must be at least one NUMA node, so returning NUMA node zero
2025-03-22 19:42:07.612565: I tensorflow/stream_executor/cuda/cuda_gpu_executor.cc:939] successful NUMA node read from SysFS had negative value (-1), but there must be at least one NUMA node, so returning NUMA node zero
2025-03-22 19:42:07.613084: I tensorflow/stream_executor/cuda/cuda_gpu_executor.cc:939] successful NUMA node read from SysFS had negative value (-1), but there must be at least one NUMA node, so returning NUMA node zero
2025-03-22 19:42:07.945970: I tensorflow/stream_executor/cuda/cuda_gpu_executor.cc:939] successful NUMA node read from SysFS had negative value (-1), but there must be at least one NUMA node, so returning NUMA node zero
2025-03-22 19:42:07.946478: I tensorflow/stream_executor/cuda/cuda_gpu_executor.cc:939] successful NUMA node read from SysFS had negative value (-1), but there must be at least one NUMA node, so returning NUMA node zero
2025-03-22 19:42:07.946924: I tensorflow/stream_executor/cuda/cuda_gpu_executor.cc:939] successful NUMA node read from SysFS had negative value (-1), but there must be at least one NUMA node, so returning NUMA node zero
2025-03-22 19:42:07.947351: I tensorflow/core/common_runtime/gpu/gpu_process_state.cc:214] Using CUDA malloc Async allocator for GPU: 0
2025-03-22 19:42:07.947770: I tensorflow/core/common_runtime/gpu/gpu_device.cc:1525] Created device /job:localhost/replica:0/task:0/device:GPU:0 with 18432 MB memory:  -> device: 0, name: NVIDIA GeForce RTX 3090, pci bus id: 0000:01:00.0, compute capability: 8.6
